Workbook

Sheet DATOS Y RESPUESTAS
J2: INVENTARIO CLÍNICO DE MILLON PARA ADOLESCENTES
Q3: MACI
A4: Nombre: | B4: NICOLE AIXA
A5: Apellidos: | B5: CONTRERAS ZURITA
A6: Sexo: | B6: FEMENINO
A7: Edad: | B7: 10
A8: Institución: | B8: VIDA PLENA
A9: Evaluador: | B9: GARCIA
A10: Fecha: | B10: 08 de agosto 2025 | F10: 2025
B13: Nº | C13: R | D13: Nº | E13: R | F13: Nº | G13: R | H13: Nº | I13: R | J13: Nº | K13: R | L13: Nº | M13: R | N13: Nº | O13: R
B14: 1 | C14: F | D14: 26 | E14: F | F14: 51 | G14: F | H14: 76 | I14: F | J14: 101 | K14: F | L14: 126 | M14: F | N14: 151 | O14: F
B15: 2 | C15: V | D15: 27 | E15: F | F15: 52 | G15: F | H15: 77 | I15: V | J15: 102 | K15: F | L15: 127 | M15: F | N15: 152 | O15: F
B16: 3 | C16: F | D16: 28 | E16: F | F16: 53 | G16: F | H16: 78 | I16: F | J16: 103 | K16: F | L16: 128 | M16: F | N16: 153 | O16: F
B17: 4 | C17: V | D17: 29 | E17: F | F17: 54 | G17: V | H17: 79 | I17: F | J17: 104 | K17: F | L17: 129 | M17: V | N17: 154 | O17: F
B18: 5 | C18: F | D18: 30 | E18: F | F18: 55 | G18: F | H18: 80 | I18: F | J18: 105 | K18: F | L18: 130 | M18: F | N18: 155 | O18: F
B19: 6 | C19: V | D19: 31 | E19: F | F19: 56 | G19: F | H19: 81 | I19: V | J19: 106 | K19: F | L19: 131 | M19: F | N19: 156 | O19: F
B20: 7 | C20: F | D20: 32 | E20: F | F20: 57 | G20: F | H20: 82 | I20: F | J20: 107 | K20: F | L20: 132 | M20: F | N20: 157 | O20: F
B21: 8 | C21: F | D21: 33 | E21: F | F21: 58 | G21: F | H21: 83 | I21: F | J21: 108 | K21: V | L21: 133 | M21: F | N21: 158 | O21: F
B22: 9 | C22: V | D22: 34 | E22: F | F22: 59 | G22: F | H22: 84 | I22: F | J22: 109 | K22: V | L22: 134 | M22: F | N22: 159 | O22: V
B23: 10 | C23: V | D23: 35 | E23: F | F23: 60 | G23: F | H23: 85 | I23: F | J23: 110 | K23: V | L23: 135 | M23: F | N23: 160 | O23: F
B24: 11 | C24: V | D24: 36 | E24: V | F24: 61 | G24: F | H24: 86 | I24: F | J24: 111 | K24: F | L24: 136 | M24: F
B25: 12 | C25: F | D25: 37 | E25: V | F25: 62 | G25: V | H25: 87 | I25: F | J25: 112 | K25: F | L25: 137 | M25: V
B26: 13 | C26: F | D26: 38 | E26: V | F26: 63 | G26: V | H26: 88 | I26: F | J26: 113 | K26: F | L26: 138 | M26: F
B27: 14 | C27: V | D27: 39 | E27: F | F27: 64 | G27: F | H27: 89 | I27: F | J27: 114 | K27: F | L27: 139 | M27: F
B28: 15 | C28: F | D28: 40 | E28: F | F28: 65 | G28: F | H28: 90 | I28: F | J28: 115 | K28: F | L28: 140 | M28: F
B29: 16 | C29: F | D29: 41 | E29: V | F29: 66 | G29: F | H29: 91 | I29: F | J29: 116 | K29: F | L29: 141 | M29: F
B30: 17 | C30: F | D30: 42 | E30: F | F30: 67 | G30: F | H30: 92 | I30: F | J30: 117 | K30: F | L30: 142 | M30: F
B31: 18 | C31: V | D31: 43 | E31: F | F31: 68 | G31: F | H31: 93 | I31: V | J31: 118 | K31: V | L31: 143 | M31: F
B32: 19 | C32: F | D32: 44 | E32: V | F32: 69 | G32: F | H32: 94 | I32: F | J32: 119 | K32: F | L32: 144 | M32: F
B33: 20 | C33: V | D33: 45 | E33: F | F33: 70 | G33: V | H33: 95 | I33: F | J33: 120 | K33: F | L33: 145 | M33: F
B34: 21 | C34: F | D34: 46 | E34: V | F34: 71 | G34: V | H34: 96 | I34: V | J34: 121 | K34: F | L34: 146 | M34: F
B35: 22 | C35: F | D35: 47 | E35: F | F35: 72 | G35: V | H35: 97 | I35: F | J35: 122 | K35: F | L35: 147 | M35: F
... B38: 25 | C38: F | D38: 50 | E38: F | F38: 75 | G38: V | H38: 100 | I38: F | J38: 125 | K38: F | L38: 150 | M38: F

Sheet RESULTADOS
BW13: VARONES 13-15 | CZ13: VARONES 16-19 | EC13: MUJERES 13-15 | FF13: MUJERES 16-19 | GK13: TB-X | GL13: AJUSTE TRANSPARENCIA | GM13: 3 | GN13: 4
V14: Nº | BW14: 1 | BX14: 2A | BY14: 2B | BZ14: 3 | CA14: 4 | CB14: 5 | CC14: 6A | CD14: 6B | CE14: 7 | CF14: 8A | CG14: 8B | CH14: 9 | CI14: A | CJ14: B | CK14: C | CL14: D | CM14: E | CN14: F | CO14: G | CP14: H | CQ14: AA | CR14: BB | CS14: CC | CT14: DD | CU14: EE | CV14: FF | CW14: GG | CX14: Y | CY14: Z | CZ14: 1 | DA14: 2A | DB14: 2B | DC14: 3 | DD14: 4 | DE14: 5 | DF14: 6A | DG14: 6B | DH14: 7 | DI14: 8A | DJ14: 8B | DK14: 9 | DL14: A | DM14: B | DN14: C | DO14: D | DP14: E | DQ14: F | DR14: G | DS14: H | DT14: AA | DU14: BB | DV14: CC | DW14: DD | DX14: EE | DY14: FF | DZ14: GG | EA14: Y | EB14: Z | EC14: 1 | ED14: 2A | EE14: 2B | EF14: 3 | EG14: 4 | EH14: 5 | EI14: 6A | EJ14: 6B | EK14: 7 | EL14: 8A | EM14: 8B | EN14: 9 | EO14: A | EP14: B | EQ14: C | ER14: D | ES14: E | ET14: F | EU14: G | EV14: H | EW14: AA | EX14: BB | EY14: CC | EZ14: DD | FA14: EE | FB14: FF | FC14: GG | FD14: Y | FE14: Z | FF14: 1 | FG14: 2A | FH14: 2B | FI14: 3 | FJ14: 4 | FK14: 5 | FL14: 6A | FM14: 6B | FN14: 7 | FO14: 8A | FP14: 8B | FQ14: 9 | FR14: A | FS14: B | FT14: C | FU14: D | FV14: E | FW14: F | FX14: G | FY14: H | FZ14: AA | GA14: BB | GB14: CC | GC14: DD | GD14: EE | GE14: FF | GF14: GG | GG14: Y | GH14: Z | GJ14: 1 | GK14: 2 | GL14: 25
V15: 176 | BV15: 0 | BW15: 0 | BX15: 0 | BY15: 7 | BZ15: 0 | CA15: 0 | CB15: 0 | CC15: 0 | CD15: 1 | CE15: 0 | CF15: 0 | CG15: 2 | CH15: 1 | CI15: 0 | CJ15: 0 | CK15: 20 | CL15: 0 | CM15: 1 | CN15: 0 | CO15: 0 | CP15: 5 | CQ15: 9 | CR15: 1 | CS15: 0 | CT15: 0 | CU15: 0 | CV15: 0 | CW15: 8 | CX15: 0 | CY15: 15 | CZ15: 0 | DA15: 1 | DB15: 4 | DC15: 0 | DD15: 0 | DE15: 0 | DF15: 0 | DG15: 1 | DH15: 0 | DI15: 0 | DJ15: 0 | DK15: 2 | DL15: 0 | DM15: 0 | DN15: 20 | DO15: 0 | DP15: 0 | DQ15: 0 | DR15: 0 | DS15: 10 | DT15: 11 | DU15: 2 | DV15: 0 | DW15: 0 | DX15: 0 | DY15: 0 | DZ15: 3 | EA15: 0 | EB15: 13 | EC15: 0 | ED15: 0 | EE15: 4 | EF15: 0 | EG15: 0 | EH15: 0 | EI15: 0 | EJ15: 5 | EK15: 0 | EL15: 0 | EM15: 1 | EN15: 1 | EO15: 0 | EP15: 1 | EQ15: 5 | ER15: 0 | ES15: 1 | ET15: 0 | EU15: 0 | EV15: 3 | EW15: 3 | EX15: 1 | EY15: 0 | EZ15: 0 | FA15: 0 | FB15: 0 | FC15: 5 | FD15: 0 | FE15: 8 | FF15: 0 | FG15: 0 | FH15: 1 | FI15: 0 | FJ15: 0 | FK15: 0 | FL15: 0 | FM15: 8 | FN15: 0 | FO15: 0 | FP15: 0 | FQ15: 1 | FR15: 0 | FS15: 1 | FT15: 9 | FU15: 0 | FV15: 1 | FW15: 0 | FX15: 0 | FY15: 1 | FZ15: 1 | GA15: 1 | GB15: 0 | GC15: 1 | GD15: 0 | GE15: 0 | GF15: 2 | GG15: 0 | GH15: 2 | GJ15: 2 | GK15: 2 | GL15: 25
V16: 177 | BV16: 1 | BW16: 0 | BX16: 0 | BY16: 10 | BZ16: 0 | CA16: 1 | CB16: 0 | CC16: 0 | CD16: 12 | CE16: 0 | CF16: 0 | CG16: 4 | CH16: 1 | CI16: 1 | CJ16: 3 | CK16: 25 | CL16: 0 | CM16: 3 | CN16: 0 | CO16: 1 | CP16: 13 | CQ16: 20 | CR16: 5 | CS16: 0 | CT16: 0 | CU16: 0 | CV16: 1 | CW16: 20 | CX16: 0 | CY16: 34 | CZ16: 0 | DA16: 1 | DB16: 4 | DC16: 0 | DD16: 0 | DE16: 0 | DF16: 0 | DG16: 5 | DH16: 0 | DI16: 0 | DJ16: 3 | DK16: 2 | DL16: 0 | DM16: 0 | DN16: 24 | DO16: 0 | DP16: 2 | DQ16: 0 | DR16: 0 | DS16: 20 | DT16: 21 | DU16: 6 | DV16: 0 | DW16: 0 | DX16: 0 | DY16: 1 | DZ16: 10 | EA16: 0 | EB16: 34 | EC16: 0 | ED16: 0 | EE16: 5 | EF16: 0 | EG16: 0 | EH16: 0 | EI16: 0 | EJ16: 20 | EK16: 0 | EL16: 0 | EM16: 2 | EN16: 1 | EO16: 0 | EP16: 1 | EQ16: 9 | ER16: 0 | ES16: 2 | ET16: 0 | EU16: 1 | EV16: 8 | EW16: 8 | EX16: 3 | EY16: 0 | EZ16: 1 | FA16: 0 | FB16: 1 | FC16: 12 | FD16: 1 | FE16: 19 | FF16: 0 | FG16: 0 | FH16: 2 | FI16: 0 | FJ16: 0 | FK16: 1 | FL16: 1 | FM16: 20 | FN16: 0 | FO16: 0 | FP16: 0 | FQ16: 1 | FR16: 1 | FS16: 1 | FT16: 16 | FU16: 0 | FV16: 2 | FW16: 1 | FX16: 0 | FY16: 6 | FZ16: 4 | GA16: 7 | GB16: 0 | GC16: 2 | GD16: 0 | GE16: 0 | GF16: 7 | GG16: 0 | GH16: 12 | GJ16: 3 | GK16: 2 | GL16: 25
V17: 178 | BV17: 2 | BW17: 0 | BX17: 1 | BY17: 12 | BZ17: 0 | CA17: 1 | CB17: 0 | CC17: 0 | CD17: 20 | CE17: 0 | CF17: 1 | CG17: 5 | CH17: 3 | CI17: 2 | CJ17: 6 | CK17: 34 | CL17: 0 | CM17: 9 | CN17: 0 | CO17: 1 | CP17: 20 | CQ17: 31 | CR17: 12 | CS17: 1 | CT17: 1 | CU17: 0 | CV17: 1 | CW17: 29 | CX17: 1 | CY17: 46 | CZ17: 0 | DA17: 1 | DB17: 10 | DC17: 0 | DD17: 0 | DE17: 0 | DF17: 0 | DG17: 11 | DH17: 0 | DI17: 0 | DJ17: 3 | DK17: 8 | DL17: 2 | DM17: 0 | DN17: 32 | DO17: 0 | DP17: 15 | DQ17: 0 | DR17: 0 | DS17: 24 | DT17: 31 | DU17: 10 | DV17: 0 | DW17: 2 | DX17: 0 | DY17: 3 | DZ17: 18 | EA17: 2 | EB17: 44 | EC17: 0 | ED17: 0 | EE17: 8 | EF17: 0 | EG17: 1 | EH17: 0 | EI17: 0 | EJ17: 27 | EK17: 0 | EL17: 0 | EM17: 3 | EN17: 3 | EO17: 1 | EP17: 2 | EQ17: 12 | ER17: 0 | ES17: 3 | ET17: 2 | EU17: 2 | EV17: 15 | EW17: 11 | EX17: 7 | EY17: 1 | EZ17: 2 | FA17: 0 | FB17: 1 | FC17: 18 | FD17: 1 | FE17: 34 | FF17: 0 | FG17: 0 | FH17: 3 | FI17: 0 | FJ17: 0 | FK17: 2 | FL17: 1 | FM17: 26 | FN17: 0 | FO17: 0 | FP17: 0 | FQ17: 5 | FR17: 2 | FS17: 1 | FT17: 20 | FU17: 0 | FV17: 8 | FW17: 2 | FX17: 1 | FY17: 13 | FZ17: 13 | GA17: 13 | GB17: 2 | GC17: 5 | GD17: 0 | GE17: 1 | GF17: 11 | GG17: 2 | GH17: 22 | GJ17: 4 | GK17: 2 | GL17: 25
V18: 179 | BV18: 3 | BW18: 0 | BX18: 3 | BY18: 20 | BZ18: 0 | CA18: 1 | CB18: 0 | CC18: 1 | CD18: 25 | CE18: 0 | CF18: 1 | CG18: 7 | CH18: 4 | CI18: 2 | CJ18: 9 | CK18: 40 | CL18: 0 | CM18: 20 | CN18: 1 | CO18: 2 | CP18: 32 | CQ18: 40 | CR18: 20 | CS18: 1 | CT18: 3 | CU18: 0 | CV18: 2 | CW18: 40 | CX18: 2 | CY18: 56 | CZ18: 0 | DA18: 1 | DB18: 14 | DC18: 0 | DD18: 0 | DE18: 0 | DF18: 0 | DG18: 20 | DH18: 0 | DI18: 0 | DJ18: 3 | DK18: 8 | DL18: 2 | DM18: 3 | DN18: 40 | DO18: 0 | DP18: 20 | DQ18: 0 | DR18: 4 | DS18: 33 | DT18: 40 | DU18: 10 | DV18: 1 | DW18: 7 | DX18: 0 | DY18: 3 | DZ18: 35 | EA18: 2 | EB18: 52 | EC18: 0 | ED18: 0 | EE18: 16 | EF18: 0 | EG18: 1 | EH18: 1 | EI18: 1 | EJ18: 34 | EK18: 0 | EL18: 1 | EM18: 5 | EN18: 4 | EO18: 3 | EP18: 2 | EQ18: 15 | ER18: 0 | ES18: 6 | ET18: 3 | EU18: 2 | EV18: 19 | EW18: 17 | EX18: 13 | EY18: 2 | EZ18: 4 | FA18: 0 | FB18: 2 | FC18: 24 | FD18: 3 | FE18: 40 | FF18: 1 | FG18: 0 | FH18: 7 | FI18: 0 | FJ18: 2 | FK18: 3 | FL18: 2 | FM18: 33 | FN18: 0 | FO18: 0 | FP18: 1 | FQ18: 5 | FR18: 4 | FS18: 1 | FT18: 24 | FU18: 0 | FV18: 13 | FW18: 5 | FX18: 2 | FY18: 20 | FZ18: 20 | GA18: 20 | GB18: 5 | GC18: 14 | GD18: 0 | GE18: 1 | GF18: 20 | GG18: 3 | GH18: 34 | GJ18: 5 | GK18: 2 | GL18: 25
V19: 180 | BV19: 4 | BW19: 0 | BX19: 4 | BY19: 25 | BZ19: 0 | CA19: 1 | CB19: 0 | CC19: 2 | CD19: 30 | CE19: 0 | CF19: 3 | CG19: 10 | CH19: 19 | CI19: 3 | CJ19: 14 | CK19: 44 | CL19: 0 | CM19: 25 | CN19: 1 | CO19: 3 | CP19: 40 | CQ19: 44 | CR19: 25 | CS19: 1 | CT19: 6 | CU19: 0 | CV19: 5 | CW19: 44 | CX19: 7 | CY19: 63 | CZ19: 0 | DA19: 1 | DB19: 20 | DC19: 0 | DD19: 2 | DE19: 0 | DF19: 0 | DG19: 25 | DH19: 0 | DI19: 0 | DJ19: 4 | DK19: 18 | DL19: 2 | DM19: 6 | DN19: 42 | DO19: 0 | DP19: 29 | DQ19: 0 | DR19: 4 | DS19: 40 | DT19: 43 | DU19: 14 | DV19: 1 | DW19: 7 | DX19: 0 | DY19: 10 | DZ19: 40 | EA19: 2 | EB19: 61 | EC19: 0 | ED19: 0 | EE19: 20 | EF19: 0 | EG19: 1 | EH19: 3 | EI19: 1 | EJ19: 40 | EK19: 0 | EL19: 2 | EM19: 6 | EN19: 8 | EO19: 4 | EP19: 3 | EQ19: 19 | ER19: 0 | ES19: 11 | ET19: 4 | EU19: 3 | EV19: 25 | EW19: 22 | EX19: 20 | EY19: 3 | EZ19: 8 | FA19: 0 | FB19: 3 | FC19: 28 | FD19: 6 | FE19: 44 | FF19: 1 | FG19: 0 | FH19: 9 | FI19: 0 | FJ19: 2 | FK19: 5 | FL19: 2 | FM19: 40 | FN19: 0 | FO19: 0 | FP19: 1 | FQ19: 12 | FR19: 5 | FS19: 3 | FT19: 26 | FU19: 0 | FV19: 20 | FW19: 9 | FX19: 3 | FY19: 24 | FZ19: 23 | GA19: 25 | GB19: 6 | GC19: 20 | GD19: 0 | GE19: 1 | GF19: 23 | GG19: 7 | GH19: 39 | GJ19: 6 | GK19: 2 | GL19: 25
V20: 181 | BV20: 5 | BW20: 0 | BX20: 7 | BY20: 31 | BZ20: 0 | CA20: 1 | CB20: 1 | CC20: 2 | CD20: 34 | CE20: 0 | CF20: 5 | CG20: 13 | CH20: 19 | CI20: 9 | CJ20: 20 | CK20: 46 | CL20: 0 | CM20: 31 | CN20: 2 | CO20: 5 | CP20: 45 | CQ20: 48 | CR20: 32 | CS20: 2 | CT20: 7 | CU20: 0 | CV20: 10 | CW20: 47 | CX20: 13 | CY20: 68 | CZ20: 0 | DA20: 3 | DB20: 23 | DC20: 0 | DD20: 2 | DE20: 0 | DF20: 0 | DG20: 27 | DH20: 0 | DI20: 0 | DJ20: 10 | DK20: 20 | DL20: 6 | DM20: 10 | DN20: 46 | DO20: 0 | DP20: 34 | DQ20: 0 | DR20: 6 | DS20: 45 | DT20: 47 | DU20: 20 | DV20: 1 | DW20: 10 | DX20: 1 | DY20: 13 | DZ20: 43 | EA20: 15 | EB20: 66 | EC20: 0 | ED20: 1 | EE20: 21 | EF20: 0 | EG20: 1 | EH20: 4 | EI20: 2 | EJ20: 42 | EK20: 0 | EL20: 5 | EM20: 7 | EN20: 9 | EO20: 6 | EP20: 4 | EQ20: 23 | ER20: 0 | ES20: 19 | ET20: 6 | EU20: 5 | EV20: 33 | EW20: 29 | EX20: 26 | EY20: 4 | EZ20: 14 | FA20: 0 | FB20: 4 | FC20: 33 | FD20: 12 | FE20: 49 | FF20: 1 | FG20: 1 | FH20: 13 | FI20: 0 | FJ20: 3 | FK20: 8 | FL20: 3 | FM20: 42 | FN20: 0 | FO20: 0 | FP20: 2 | FQ20: 12 | FR20: 7 | FS20: 3 | FT20: 29 | FU20: 0 | FV20: 25 | FW20: 15 | FX20: 8 | FY20: 26 | FZ20: 28 | GA20: 30 | GB20: 13 | GC20: 23 | GD20: 0 | GE20: 2 | GF20: 26 | GG20: 22 | GH20: 43 | GJ20: 7 | GK20: 2 | GL20: 25
V21: 182 | BV21: 6 | BW21: 1 | BX21: 9 | BY21: 35 | BZ21: 0 | CA21: 1 | CB21: 1 | CC21: 3 | CD21: 40 | CE21: 0 | CF21: 6 | CG21: 16 | CH21: 28 | CI21: 12 | CJ21: 22 | CK21: 50 | CL21: 0 | CM21: 40 | CN21: 2 | CO21: 6 | CP21: 50 | CQ21: 50 | CR21: 35 | CS21: 2 | CT21: 12 | CU21: 1 | CV21: 20 | CW21: 50 | CX21: 21 | CY21: 72 | CZ21: 0 | DA21: 5 | DB21: 26 | DC21: 0 | DD21: 2 | DE21: 0 | DF21: 1 | DG21: 33 | DH21: 0 | DI21: 0 | DJ21: 10 | DK21: 24 | DL21: 10 | DM21: 15 | DN21: 50 | DO21: 0 | DP21: 40 | DQ21: 0 | DR21: 13 | DS21: 49 | DT21: 50 | DU21: 24 | DV21: 1 | DW21: 12 | DX21: 1 | DY21: 20 | DZ21: 46 | EA21: 23 | EB21: 69 | EC21: 0 | ED21: 2 | EE21: 25 | EF21: 0 | EG21: 1 | EH21: 5 | EI21: 2 | EJ21: 43 | EK21: 0 | EL21: 7 | EM21: 10 | EN21: 17 | EO21: 9 | EP21: 5 | EQ21: 30 | ER21: 0 | ES21: 32 | ET21: 10 | EU21: 8 | EV21: 40 | EW21: 35 | EX21: 31 | EY21: 6 | EZ21: 20 | FA21: 0 | FB21: 7 | FC21: 40 | FD21: 21 | FE21: 53 | FF21: 1 | FG21: 2 | FH21: 16 | FI21: 0 | FJ21: 7 | FK21: 12 | FL21: 5 | FM21: 43 | FN21: 0 | FO21: 2 | FP21: 4 | FQ21: 18 | FR21: 9 | FS21: 4 | FT21: 33 | FU21: 0 | FV21: 30 | FW21: 20 | FX21: 14 | FY21: 31 | FZ21: 31 | GA21: 36 | GB21: 20 | GC21: 27 | GD21: 0 | GE21: 4 | GF21: 30 | GG21: 34 | GH21: 47 | GJ21: 8 | GK21: 2 | GL21: 25
V22: 183 | BV22: 7 | BW22: 2 | BX22: 9 | BY22: 40 | BZ22: 0 | CA22: 1 | CB22: 1 | CC22: 3 | CD22: 42 | CE22: 0 | CF22: 9 | CG22: 20 | CH22: 28 | CI22: 20 | CJ22: 25 | CK22: 55 | CL22: 0 | CM22: 44 | CN22: 3 | CO22: 12 | CP22: 54 | CQ22: 53 | CR22: 40 | CS22: 2 | CT22: 20 | CU22: 1 | CV22: 24 | CW22: 53 | CX22: 34 | CY22: 74 | CZ22: 0 | DA22: 7 | DB22: 30 | DC22: 0 | DD22: 2 | DE22: 1 | DF22: 1 | DG22: 40 | DH22: 0 | DI22: 2 | DJ22: 14 | DK22: 26 | DL22: 15 | DM22: 20 | DN22: 53 | DO22: 0 | DP22: 44 | DQ22: 0 | DR22: 15 | DS22: 50 | DT22: 54 | DU22: 26 | DV22: 1 | DW22: 20 | DX22: 1 | DY22: 22 | DZ22: 50 | EA22: 34 | EB22: 72 | EC22: 0 | ED22: 3 | EE22: 29 | EF22: 0 | EG22: 1 | EH22: 7 | EI22: 7 | EJ22: 45 | EK22: 0 | EL22: 10 | EM22: 11 | EN22: 17 | EO22: 13 | EP22: 6 | EQ22: 35 | ER22: 0 | ES22: 40 | ET22: 13 | EU22: 12 | EV22: 42 | EW22: 37 | EX22: 40 | EY22: 9 | EZ22: 28 | FA22: 0 | FB22: 9 | FC22: 42 | FD22: 34 | FE22: 58 | FF22: 1 | FG22: 2 | FH22: 20 | FI22: 0 | FJ22: 8 | FK22: 14 | FL22: 7 | FM22: 45 | FN22: 0 | FO22: 4 | FP22: 7 | FQ22: 20 | FR22: 12 | FS22: 6 | FT22: 34 | FU22: 0 | FV22: 40 | FW22: 23 | FX22: 20 | FY22: 37 | FZ22: 35 | GA22: 40 | GB22: 24 | GC22: 30 | GD22: 0 | GE22: 7 | GF22: 35 | GG22: 43 | GH22: 50 | GJ22: 9 | GK22: 2 | GL22: 25
V23: 184 | BV23: 8 | BW23: 3 | BX23: 14 | BY23: 41 | BZ23: 0 | CA23: 1 | CB23: 1 | CC23: 5 | CD23: 44 | CE23: 0 | CF23: 13 | CG23: 23 | CH23: 37 | CI23: 25 | CJ23: 26 | CK23: 57 | CL23: 0 | CM23: 48 | CN23: 4 | CO23: 20 | CP23: 60 | CQ23: 56 | CR23: 42 | CS23: 3 | CT23: 25 | CU23: 2 | CV23: 31 | CW23: 57 | CX23: 38 | CY23: 77 | CZ23: 0 | DA23: 8 | DB23: 36 | DC23: 0 | DD23: 2 | DE23: 3 | DF23: 1 | DG23: 42 | DH23: 0 | DI23: 5 | DJ23: 20 | DK23: 32 | DL23: 20 | DM23: 23 | DN23: 55 | DO23: 0 | DP23: 46 | DQ23: 0 | DR23: 20 | DS23: 58 | DT23: 57 | DU23: 31 | DV23: 1 | DW23: 22 | DX23: 1 | DY23: 25 | DZ23: 52 | EA23: 37 | EB23: 74 | EC23: 2 | ED23: 4 | EE23: 31 | EF23: 0 | EG23: 3 | EH23: 10 | EI23: 8 | EJ23: 46 | EK23: 0 | EL23: 13 | EM23: 13 | EN23: 25 | EO23: 15 | EP23: 7 | EQ23: 40 | ER23: 0 | ES23: 43 | ET23: 16 | EU23: 19 | EV23: 44 | EW23: 40 | EX23: 44 | EY23: 11 | EZ23: 33 | FA23: 0 | FB23: 12 | FC23: 43 | FD23: 41 | FE23: 62 | FF23: 2 | FG23: 3 | FH23: 22 | FI23: 0 | FJ23: 9 | FK23: 16 | FL23: 8 | FM23: 47 | FN23: 0 | FO23: 7 | FP23: 8 | FQ23: 23 | FR23: 15 | FS23: 6 | FT23: 37 | FU23: 0 | FV23: 43 | FW23: 26 | FX23: 23 | FY23: 40 | FZ23: 36 | GA23: 42 | GB23: 29 | GC23: 35 | GD23: 0 | GE23: 7 | GF23: 38 | GG23: 50 | GH23: 54 | GJ23: 10 | GK23: 2 | GL23: 25
V24: 185 | BV24: 9 | BW24: 8 | BX24: 20 | BY24: 43 | BZ24: 0 | CA24: 1 | CB24: 1 | CC24: 6 | CD24: 46 | CE24: 0 | CF24: 16 | CG24: 25 | CH24: 39 | CI24: 30 | CJ24: 27 | CK24: 60 | CL24: 0 | CM24: 50 | CN24: 5 | CO24: 26 | CP24: 63 | CQ24: 58 | CR24: 44 | CS24: 4 | CT24: 28 | CU24: 3 | CV24: 35 | CW24: 59 | CX24: 43 | CY24: 80 | CZ24: 6 | DA24: 12 | DB24: 40 | DC24: 0 | DD24: 3 | DE24: 3 | DF24: 4 | DG24: 43 | DH24: 0 | DI24: 10 | DJ24: 22 | DK24: 34 | DL24: 23 | DM24: 26 | DN24: 57 | DO24: 0 | DP24: 50 | DQ24: 0 | DR24: 23 | DS24: 60 | DT24: 59 | DU24: 34 | DV24: 4 | DW24: 24 | DX24: 1 | DY24: 33 | DZ24: 53 | EA24: 42 | EB24: 77 | EC24: 2 | ED24: 6 | EE24: 33 | EF24: 0 | EG24: 5 | EH24: 15 | EI24: 16 | EJ24: 48 | EK24: 1 | EL24: 17 | EM24: 16 | EN24: 25 | EO24: 20 | EP24: 8 | EQ24: 41 | ER24: 0 | ES24: 47 | ET24: 20 | EU24: 28 | EV24: 47 | EW24: 42 | EX24: 48 | EY24: 15 | EZ24: 40 | FA24: 1 | FB24: 14 | FC24: 45 | FD24: 50 | FE24: 65 | FF24: 2 | FG24: 6 | FH24: 27 | FI24: 0 | FJ24: 10 | FK24: 20 | FL24: 11 | FM24: 50 | FN24: 0 | FO24: 11 | FP24: 10 | FQ24: 24 | FR24: 20 | FS24: 9 | FT24: 40 | FU24: 0 | FV24: 48 | FW24: 30 | FX24: 27 | FY24: 43 | FZ24: 38 | GA24: 45 | GB24: 33 | GC24: 40 | GD24: 0 | GE24: 14 | GF24: 40 | GG24: 58 | GH24: 60 | GJ24: 11 | GK24: 2 | GL24: 25
BV25: 10 | BW25: 11 | BX25: 22 | BY25: 45 | BZ25: 0 | CA25: 2 | CB25: 2 | CC25: 8 | CD25: 48 | CE25: 0 | CF25: 17 | CG25: 28 | CH25: 43 | CI25: 4 | CJ25: 29 | CK25: 64 | CL25: 0 | CM25: 55 | CN25: 5 | CO25: 35 | CP25: 67 | CQ25: 60 | CR25: 47 | CS25: 5 | CT25: 32 | CU25: 3 | CV25: 40 | CW25: 61 | CX25: 51 | CY25: 82 | CZ25: 9 | DA25: 20 | DB25: 43 | DC25: 0 | DD25: 3 | DE25: 4 | DF25: 4 | DG25: 45 | DH25: 0 | DI25: 11 | DJ25: 24 | DK25: 40 | DL25: 27 | DM25: 29 | DN25: 60 | DO25: 0 | DP25: 55 | DQ25: 5 | DR25: 27 | DS25: 61 | DT25: 60 | DU25: 38 | DV25: 6 | DW25: 26 | DX25: 1 | DY25: 40 | DZ25: 57 | EA25: 45 | EB25: 82 | EC25: 4 | ED25: 7 | EE25: 37 | EF25: 0 | EG25: 7 | EH25: 20 | EI25: 20 | EJ25: 50 | EK25: 1 | EL25: 20 | EM25: 20 | EN25: 32 | EO25: 25 | EP25: 11 | EQ25: 43 | ER25: 0 | ES25: 50 | ET25: 25 | EU25: 35 | EV25: 50 | EW25: 43 | EX25: 50 | EY25: 17 | EZ25: 42 | FA25: 1 | FB25: 17 | FC25: 47 | FD25: 60 | FE25: 69 | FF25: 2 | FG25: 7 | FH25: 29 | FI25: 0 | FJ25: 10 | FK25: 25 | FL25: 16 | FM25: 56 | FN25: 0 | FO25: 15 | FP25: 12 | FQ25: 28 | FR25: 23 | FS25: 10 | FT25: 41 | FU25: 0 | FV25: 50 | FW25: 34 | FX25: 30 | FY25: 46 | FZ25: 40 | GA25: 46 | GB25: 38 | GC25: 42 | GD25: 0 | GE25: 16 | GF25: 42 | GG25: 66 | GH25: 64 | GJ25: 12 | GK25: 2 | GL25: 25
BV26: 11 | BW26: 16 | BX26: 25 | BY26: 46 | BZ26: 0 | CA26: 3 | CB26: 2 | CC26: 10 | CD26: 50 | CE26: 0 | CF26: 20 | CG26: 30 | CH26: 44 | CI26: 40 | CJ26: 32 | CK26: 66 | CL26: 1 | CM26: 61 | CN26: 6 | CO26: 37 | CP26: 69 | CQ26: 61 | CR26: 48 | CS26: 6 | CT26: 35 | CU26: 3 | CV26: 42 | CW26: 62 | CX26: 58 | CY26: 84 | CZ26: 9 | DA26: 25 | DB26: 44 | DC26: 0 | DD26: 6 | DE26: 4 | DF26: 6 | DG26: 47 | DH26: 0 | DI26: 17 | DJ26: 25 | DK26: 41 | DL26: 31 | DM26: 31 | DN26: 62 | DO26: 1 | DP26: 58 | DQ26: 7 | DR26: 30 | DS26: 65 | DT26: 63 | DU26: 40 | DV26: 6 | DW26: 28 | DX26: 1 | DY26: 43 | DZ26: 60 | EA26: 64 | EB26: 84 | EC26: 5 | ED26: 11 | EE26: 40 | EF26: 0 | EG26: 9 | EH26: 21 | EI26: 21 | EJ26: 53 | EK26: 1 | EL26: 22 | EM26: 22 | EN26: 34 | EO26: 30 | EP26: 15 | EQ26: 45 | ER26: 0 | ES26: 52 | ET26: 30 | EU26: 40 | EV26: 54 | EW26: 45 | EX26: 55 | EY26: 24 | EZ26: 45 | FA26: 1 | FB26: 20 | FC26: 49 | FD26: 68 | FE26: 75 | FF26: 3 | FG26: 10 | FH26: 32 | FI26: 0 | FJ26: 12 | FK26: 26 | FL26: 20 | FM26: 59 | FN26: 0 | FO26: 20 | FP26: 13 | FQ26: 29 | FR26: 28 | FS26: 15 | FT26: 42 | FU26: 1 | FV26: 54 | FW26: 40 | FX26: 32 | FY26: 50 | FZ26: 42 | GA26: 50 | GB26: 40 | GC26: 44 | GD26: 0 | GE26: 20 | GF26: 43 | GG26: 74 | GH26: 69 | GJ26: 13 | GK26: 2 | GL26: 25
BV27: 12 | BW27: 20 | BX27: 29 | BY27: 47 | BZ27: 1 | CA27: 4 | CB27: 3 | CC27: 12 | CD27: 55 | CE27: 0 | CF27: 24 | CG27: 33 | CH27: 46 | CI27: 43 | CJ27: 35 | CK27: 69 | CL27: 1 | CM27: 64 | CN27: 8 | CO27: 42 | CP27: 71 | CQ27: 63 | CR27: 50 | CS27: 9 | CT27: 40 | CU27: 4 | CV27: 44 | CW27: 65 | CX27: 67 | CY27: 90 | CZ27: 10 | DA27: 31 | DB27: 45 | DC27: 0 | DD27: 6 | DE27: 4 | DF27: 7 | DG27: 50 | DH27: 0 | DI27: 20 | DJ27: 26 | DK27: 45 | DL27: 35 | DM27: 33 | DN27: 65 | DO27: 3 | DP27: 62 | DQ27: 12 | DR27: 33 | DS27: 69 | DT27: 66 | DU27: 41 | DV27: 7 | DW27: 35 | DX27: 1 | DY27: 46 | DZ27: 62 | EA27: 74 | EB27: 90 | EC27: 6 | ED27: 14 | EE27: 41 | EF27: 1 | EG27: 11 | EH27: 23 | EI27: 23 | EJ27: 58 | EK27: 1 | EL27: 24 | EM27: 23 | EN27: 40 | EO27: 35 | EP27: 17 | EQ27: 46 | ER27: 1 | ES27: 55 | ET27: 35 | EU27: 42 | EV27: 56 | EW27: 46 | EX27: 58 | EY27: 32 | EZ27: 48 | FA27: 1 | FB27: 24 | FC27: 50 | FD27: 75 | FE27: 81 | FF27: 4 | FG27: 12 | FH27: 34 | FI27: 0 | FJ27: 16 | FK27: 28 | FL27: 24 | FM27: 63 | FN27: 0 | FO27: 23 | FP27: 15 | FQ27: 34 | FR27: 32 | FS27: 18 | FT27: 43 | FU27: 1 | FV27: 57 | FW27: 41 | FX27: 35 | FY27: 53 | FZ27: 43 | GA27: 53 | GB27: 43 | GC27: 46 | GD27: 0 | GE27: 23 | GF27: 44 | GG27: 81 | GH27: 74 | GJ27: 14 | GK27: 2 | GL27: 25
BV28: 13 | BW28: 21 | BX28: 32 | BY28: 48 | BZ28: 1 | CA28: 5 | CB28: 5 | CC28: 13 | CD28: 58 | CE28: 0 | CF28: 28 | CG28: 36 | CH28: 47 | CI28: 47 | CJ28: 40 | CK28: 71 | CL28: 2 | CM28: 67 | CN28: 9 | CO28: 45 | CP28: 72 | CQ28: 65 | CR28: 52 | CS28: 12 | CT28: 43 | CU28: 5 | CV28: 46 | CW28: 66 | CX28: 74 | CY28: 95 | CZ28: 16 | DA28: 36 | DB28: 46 | DC28: 0 | DD28: 6 | DE28: 6 | DF28: 12 | DG28: 55 | DH28: 0 | DI28: 24 | DJ28: 29 | DK28: 46 | DL28: 40 | DM28: 37 | DN28: 73 | DO28: 4 | DP28: 64 | DQ28: 15 | DR28: 40 | DS28: 73 | DT28: 67 | DU28: 43 | DV28: 12 | DW28: 40 | DX28: 2 | DY28: 47 | DZ28: 64 | EA28: 78 | EB28: 91 | EC28: 9 | ED28: 16 | EE28: 42 | EF28: 1 | EG28: 14 | EH28: 25 | EI28: 27 | EJ28: 61 | EK28: 1 | EL28: 26 | EM28: 25 | EN28: 41 | EO28: 40 | EP28: 19 | EQ28: 47 | ER28: 2 | ES28: 59 | ET28: 40 | EU28: 44 | EV28: 60 | EW28: 47 | EX28: 60 | EY28: 40 | EZ28: 50 | FA28: 1 | FB28: 29 | FC28: 51 | FD28: 85 | FE28: 85 | FF28: 7 | FG28: 14 | FH28: 35 | FI28: 0 | FJ28: 18 | FK28: 31 | FL28: 29 | FM28: 66 | FN28: 0 | FO28: 24 | FP28: 18 | FQ28: 35 | FR28: 35 | FS28: 20 | FT28: 44 | FU28: 1 | FV28: 60 | FW28: 44 | FX28: 40 | FY28: 58 | FZ28: 44 | GA28: 55 | GB28: 45 | GC28: 47 | GD28: 1 | GE28: 24 | GF28: 46 | GG28: 84 | GH28: 80 | GJ28: 15 | GK28: 2 | GL28: 25
BV29: 14 | BW29: 24 | BX29: 36 | BY29: 50 | BZ29: 1 | CA29: 7 | CB29: 5 | CC29: 16 | CD29: 62 | CE29: 0 | CF29: 31 | CG29: 40 | CH29: 50 | CI29: 50 | CJ29: 42 | CK29: 72 | CL29: 3 | CM29: 70 | CN29: 14 | CO29: 48 | CP29: 75 | CQ29: 66 | CR29: 55 | CS29: 17 | CT29: 45 | CU29: 6 | CV29: 48 | CW29: 68 | CX29: 84 | CY29: 97 | CZ29: 20 | DA29: 40 | DB29: 48 | DC29: 1 | DD29: 6 | DE29: 9 | DF29: 13 | DG29: 60 | DH29: 0 | DI29: 26 | DJ29: 31 | DK29: 50 | DL29: 42 | DM29: 40 | DN29: 74 | DO29: 6 | DP29: 69 | DQ29: 17 | DR29: 43 | DS29: 75 | DT29: 68 | DU29: 45 | DV29: 12 | DW29: 43 | DX29: 2 | DY29: 48 | DZ29: 64 | EA29: 84 | EB29: 98 | EC29: 12 | ED29: 18 | EE29: 43 | EF29: 1 | EG29: 19 | EH29: 27 | EI29: 29 | EJ29: 66 | EK29: 2 | EL29: 28 | EM29: 27 | EN29: 43 | EO29: 43 | EP29: 21 | EQ29: 48 | ER29: 3 | ES29: 61 | ET29: 42 | EU29: 46 | EV29: 62 | EW29: 48 | EX29: 62 | EY29: 43 | EZ29: 53 | FA29: 1 | FB29: 30 | FC29: 53 | FD29: 94 | FE29: 92 | FF29: 12 | FG29: 19 | FH29: 38 | FI29: 0 | FJ29: 20 | FK29: 34 | FL29: 33 | FM29: 69 | FN29: 0 | FO29: 26 | FP29: 20 | FQ29: 40 | FR29: 37 | FS29: 21 | FT29: 45 | FU29: 2 | FV29: 62 | FW29: 48 | FX29: 43 | FY29: 60 | FZ29: 45 | GA29: 57 | GB29: 47 | GC29: 50 | GD29: 2 | GE29: 25 | GF29: 47 | GG29: 94 | GH29: 84 | GJ29: 16 | GK29: 2 | GL29: 25
BV30: 15 | BW30: 27 | BX30: 40 | BY30: 53 | BZ30: 1 | CA30: 8 | CB30: 6 | CC30: 20 | CD30: 66 | CE30: 0 | CF30: 35 | CG30: 41 | CH30: 53 | CI30: 53 | CJ30: 43 | CK30: 73 | CL30: 5 | CM30: 71 | CN30: 20 | CO30: 50 | CP30: 79 | CQ30: 67 | CR30: 58 | CS30: 20 | CT30: 48 | CU30: 7 | CV30: 50 | CW30: 68 | CX30: 93 | CY30: 99 | CZ30: 22 | DA30: 41 | DB30: 49 | DC30: 1 | DD30: 8 | DE30: 12 | DF30: 13 | DG30: 66 | DH30: 1 | DI30: 29 | DJ30: 34 | DK30: 51 | DL30: 44 | DM30: 41 | DN30: 75 | DO30: 8 | DP30: 72 | DQ30: 20 | DR30: 46 | DS30: 80 | DT30: 69 | DU30: 47 | DV30: 20 | DW30: 46 | DX30: 6 | DY30: 50 | DZ30: 65 | EA30: 92 | EB30: 99 | EC30: 17 | ED30: 20 | EE30: 44 | EF30: 1 | EG30: 20 | EH30: 28 | EI30: 33 | EJ30: 68 | EK30: 2 | EL30: 31 | EM30: 29 | EN30: 45 | EO30: 45 | EP30: 24 | EQ30: 49 | ER30: 4 | ES30: 64 | ET30: 45 | EU30: 48 | EV30: 66 | EW30: 49 | EX30: 64 | EY30: 46 | EZ30: 57 | FA30: 1 | FB30: 35 | FC30: 55 | FD30: 98 | FE30: 98 | FF30: 16 | FG30: 20 | FH30: 40 | FI30: 0 | FJ30: 21 | FK30: 40 | FL30: 35 | FM30: 74 | FN30: 0 | FO30: 27 | FP30: 21 | FQ30: 41 | FR30: 40 | FS30: 23 | FT30: 46 | FU30: 2 | FV30: 64 | FW30: 50 | FX30: 45 | FY30: 65 | FZ30: 46 | GA30: 58 | GB30: 50 | GC30: 53 | GD30: 2 | GE30: 27 | GF30: 48 | GG30: 96 | GH30: 96 | GJ30: 17 | GK30: 2 | GL30: 25
BV31: 16 | BW31: 32 | BX31: 42 | BY31: 55 | BZ31: 1 | CA31: 9 | CB31: 7 | CC31: 22 | CD31: 69 | CE31: 1 | CF31: 38 | CG31: 42 | CH31: 58 | CI31: 58 | CJ31: 44 | CK31: 75 | CL31: 9 | CM31: 73 | CN31: 23 | CO31: 53 | CP31: 82 | CQ31: 69 | CR31: 61 | CS31: 25 | CT31: 50 | CU31: 8 | CV31: 54 | CW31: 69 | CX31: 98 | CY31: 100 | CZ31: 28 | DA31: 42 | DB31: 50 | DC31: 1 | DD31: 8 | DE31: 14 | DF31: 13 | DG31: 68 | DH31: 1 | DI31: 33 | DJ31: 36 | DK31: 57 | DL31: 48 | DM31: 43 | DN31: 78 | DO31: 12 | DP31: 72 | DQ31: 23 | DR31: 50 | DS31: 85 | DT31: 70 | DU31: 49 | DV31: 23 | DW31: 47 | DX31: 6 | DY31: 52 | DZ31: 67 | EA31: 98 | EB31: 100 | EC31: 20 | ED31: 24 | EE31: 45 | EF31: 1 | EG31: 21 | EH31: 31 | EI31: 36 | EJ31: 70 | EK31: 2 | EL31: 35 | EM31: 30 | EN31: 48 | EO31: 48 | EP31: 27 | EQ31: 50 | ER31: 4 | ES31: 66 | ET31: 47 | EU31: 50 | EV31: 68 | EW31: 50 | EX31: 66 | EY31: 48 | EZ31: 60 | FA31: 1 | FB31: 38 | FC31: 56 | FD31: 99 | FE31: 100 | FF31: 20 | FG31: 21 | FH31: 42 | FI31: 1 | FJ31: 23 | FK31: 42 | FL31: 40 | FM31: 75 | FN31: 2 | FO31: 28 | FP31: 22 | FQ31: 42 | FR31: 42 | FS31: 24 | FT31: 47 | FU31: 2 | FV31: 66 | FW31: 53 | FX31: 47 | FY31: 69 | FZ31: 47 | GA31: 60 | GB31: 55 | GC31: 57 | GD31: 2 | GE31: 29 | GF31: 50 | GG31: 98 | GH31: 100 | GJ31: 18 | GK31: 2 | GL31: 25
BV32: 17 | BW32: 36 | BX32: 43 | BY32: 58 | BZ32: 2 | CA32: 10 | CB32: 9 | CC32: 25 | CD32: 71 | CE32: 1 | CF32: 40 | CG32: 43 | CH32: 60 | CI32: 61 | CJ32: 45 | CK32: 77 | CL32: 12 | CM32: 75 | CN32: 26 | CO32: 57 | CP32: 85 | CQ32: 70 | CR32: 65 | CS32: 29 | CT32: 53 | CU32: 9 | CV32: 57 | CW32: 70 | CX32: 100 | CY32: 100 | CZ32: 33 | DA32: 43 | DB32: 52 | DC32: 1 | DD32: 9 | DE32: 17 | DF32: 20 | DG32: 72 | DH32: 1 | DI32: 35 | DJ32: 40 | DK32: 58 | DL32: 50 | DM32: 45 | DN32: 81 | DO32: 15 | DP32: 73 | DQ32: 25 | DR32: 55 | DS32: 100 | DT32: 71 | DU32: 50 | DV32: 26 | DW32: 50 | DX32: 6 | DY32: 53 | DZ32: 69 | EA32: 100 | EB32: 100 | EC32: 22 | ED32: 25 | EE32: 47 | EF32: 1 | EG32: 23 | EH32: 33 | EI32: 40 | EJ32: 72 | EK32: 3 | EL32: 40 | EM32: 32 | EN32: 50 | EO32: 50 | EP32: 32 | EQ32: 51 | ER32: 5 | ES32: 68 | ET32: 50 | EU32: 55 | EV32: 70 | EW32: 51 | EX32: 68 | EY32: 50 | EZ32: 64 | FA32: 2 | FB32: 40 | FC32: 57 | FD32: 100 | FE32: 100 | FF32: 21 | FG32: 25 | FH32: 43 | FI32: 1 | FJ32: 25 | FK32: 44 | FL32: 41 | FM32: 80 | FN32: 2 | FO32: 30 | FP32: 25 | FQ32: 43 | FR32: 45 | FS32: 25 | FT32: 48 | FU32: 2 | FV32: 68 | FW32: 56 | FX32: 48 | FY32: 71 | FZ32: 48 | GA32: 62 | GB32: 58 | GC32: 60 | GD32: 2 | GE32: 31 | GF32: 51 | GG32: 100 | GH32: 100 | GJ32: 19 | GK32: 2 | GL32: 25
BV33: 18 | BW33: 40 | BX33: 44 | BY33: 61 | BZ33: 2 | CA33: 11 | CB33: 15 | CC33: 26 | CD33: 75 | CE33: 1 | CF33: 41 | CG33: 44 | CH33: 65 | CI33: 64 | CJ33: 46 | CK33: 79 | CL33: 14 | CM33: 77 | CN33: 29 | CO33: 62 | CP33: 97 | CQ33: 71 | CR33: 67 | CS33: 34 | CT33: 58 | CU33: 11 | CV33: 59 | CW33: 71 | CX33: 100 | CY33: 100 | CZ33: 36 | DA33: 44 | DB33: 54 | DC33: 1 | DD33: 9 | DE33: 17 | DF33: 20 | DG33: 75 | DH33: 1 | DI33: 40 | DJ33: 41 | DK33: 60 | DL33: 54 | DM33: 46 | DN33: 81 | DO33: 20 | DP33: 75 | DQ33: 30 | DR33: 59 | DS33: 103 | DT33: 72 | DU33: 52 | DV33: 30 | DW33: 54 | DX33: 12 | DY33: 53 | DZ33: 70 | EA33: 100 | EB33: 100 | EC33: 26 | ED33: 28 | EE33: 48 | EF33: 1 | EG33: 26 | EH33: 36 | EI33: 42 | EJ33: 75 | EK33: 4 | EL33: 41 | EM33: 35 | EN33: 53 | EO33: 52 | EP33: 34 | EQ33: 53 | ER33: 6 | ES33: 69 | ET33: 53 | EU33: 58 | EV33: 73 | EW33: 52 | EX33: 69 | EY33: 55 | EZ33: 66 | FA33: 2 | FB33: 41 | FC33: 59 | FD33: 100 | FE33: 100 | FF33: 23 | FG33: 26 | FH33: 44 | FI33: 1 | FJ33: 29 | FK33: 45 | FL33: 42 | FM33: 82 | FN33: 2 | FO33: 33 | FP33: 26 | FQ33: 45 | FR33: 47 | FS33: 26 | FT33: 50 | FU33: 5 | FV33: 70 | FW33: 59 | FX33: 50 | FY33: 72 | FZ33: 49 | GA33: 63 | GB33: 62 | GC33: 63 | GD33: 2 | GE33: 34 | GF33: 52 | GG33: 100 | GH33: 100 | GJ33: 20 | GK33: 2 | GL33: 25
BV34: 19 | BW34: 41 | BX34: 46 | BY34: 63 | BZ34: 2 | CA34: 12 | CB34: 16 | CC34: 29 | CD34: 79 | CE34: 2 | CF34: 43 | CG34: 46 | CH34: 67 | CI34: 68 | CJ34: 48 | CK34: 82 | CL34: 17 | CM34: 80 | CN34: 32 | CO34: 66 | CP34: 98 | CQ34: 72 | CR34: 70 | CS34: 40 | CT34: 61 | CU34: 12 | CV34: 61 | CW34: 72 | CX34: 100 | CY34: 100 | CZ34: 40 | DA34: 45 | DB34: 57 | DC34: 1 | DD34: 1 | DE34: 20 | DF34: 21 | DG34: 79 | DH34: 3 | DI34: 42 | DJ34: 42 | DK34: 62 | DL34: 57 | DM34: 48 | DN34: 83 | DO34: 23 | DP34: 77 | DQ34: 32 | DR34: 63 | DS34: 107 | DT34: 73 | DU34: 55 | DV34: 36 | DW34: 58 | DX34: 12 | DY34: 56 | DZ34: 71 | EA34: 100 | EB34: 100 | EC34: 29 | ED34: 31 | EE34: 49 | EF34: 1 | EG34: 28 | EH34: 38 | EI34: 44 | EJ34: 77 | EK34: 4 | EL34: 42 | EM34: 38 | EN34: 54 | EO34: 54 | EP34: 36 | EQ34: 55 | ER34: 7 | ES34: 71 | ET34: 56 | EU34: 60 | EV34: 75 | EW34: 54 | EX34: 71 | EY34: 59 | EZ34: 67 | FA34: 3 | FB34: 42 | FC34: 60 | FD34: 100 | FE34: 100 | FF34: 25 | FG34: 29 | FH34: 45 | FI34: 1 | FJ34: 31 | FK34: 46 | FL34: 44 | FM34: 85 | FN34: 3 | FO34: 35 | FP34: 28 | FQ34: 46 | FR34: 49 | FS34: 28 | FT34: 53 | FU34: 5 | FV34: 71 | FW34: 61 | FX34: 53 | FY34: 74 | FZ34: 50 | GA34: 65 | GB34: 65 | GC34: 65 | GD34: 2 | GE34: 36 | GF34: 54 | GG34: 100 | GH34: 100 | GJ34: 21 | GK34: 2 | GL34: 25
BV35: 20 | BW35: 43 | BX35: 48 | BY35: 65 | BZ35: 3 | CA35: 13 | CB35: 20 | CC35: 31 | CD35: 83 | CE35: 2 | CF35: 44 | CG35: 47 | CH35: 68 | CI35: 70 | CJ35: 50 | CK35: 85 | CL35: 19 | CM35: 81 | CN35: 36 | CO35: 69 | CP35: 100 | CQ35: 73 | CR35: 72 | CS35: 43 | CT35: 64 | CU35: 15 | CV35: 63 | CW35: 72 | CX35: 100 | CY35: 100 | CZ35: 41 | DA35: 47 | DB35: 60 | DC35: 1 | DD35: 16 | DE35: 21 | DF35: 22 | DG35: 79 | DH35: 3 | DI35: 43 | DJ35: 44 | DK35: 64 | DL35: 60 | DM35: 50 | DN35: 83 | DO35: 25 | DP35: 80 | DQ35: 35 | DR35: 67 | DS35: 107 | DT35: 73 | DU35: 57 | DV35: 40 | DW35: 62 | DX35: 16 | DY35: 57 | DZ35: 72 | EA35: 100 | EB35: 100 | EC35: 33 | ED35: 34 | EE35: 50 | EF35: 1 | EG35: 30 | EH35: 40 | EI35: 45 | EJ35: 79 | EK35: 5 | EL35: 43 | EM35: 40 | EN35: 57 | EO35: 56 | EP35: 39 | EQ35: 58 | ER35: 7 | ES35: 73 | ET35: 59 | EU35: 63 | EV35: 77 | EW35: 56 | EX35: 72 | EY35: 63 | EZ35: 69 | FA35: 4 | FB35: 43 | FC35: 62 | FD35: 100 | FE35: 100 | FF35: 28 | FG35: 31 | FH35: 46 | FI35: 1 | FJ35: 34 | FK35: 47 | FL35: 45 | FM35: 89 | FN35: 4 | FO35: 38 | FP35: 30 | FQ35: 48 | FR35: 50 | FS35: 29 | FT35: 57 | FU35: 11 | FV35: 73 | FW35: 64 | FX35: 56 | FY35: 75 | FZ35: 52 | GA35: 66 | GB35: 68 | GC35: 66 | GD35: 5 | GE35: 39 | GF35: 56 | GG35: 100 | GH35: 100 | GJ35: 22 | GK35: 2 | GL35: 25
BV36: 21 | BW36: 44 | BX36: 49 | BY36: 66 | BZ36: 4 | CA36: 15 | CB36: 21 | CC36: 34 | CD36: 85 | CE36: 3 | CF36: 46 | CG36: 48 | CH36: 69 | CI36: 71 | CJ36: 51 | CK36: 92 | CL36: 20 | CM36: 82 | CN36: 40 | CO36: 72 | CP36: 102 | CQ36: 74 | CR36: 73 | CS36: 45 | CT36: 67 | CU36: 17 | CV36: 65 | CW36: 73 | CX36: 100 | CY36: 100 | CZ36: 43 | DA36: 48 | DB36: 62 | DC36: 1 | DD36: 16 | DE36: 22 | DF36: 24 | DG36: 85 | DH36: 3 | DI36: 44 | DJ36: 46 | DK36: 67 | DL36: 62 | DM36: 51 | DN36: 85 | DO36: 28 | DP36: 82 | DQ36: 40 | DR36: 69 | DS36: 107 | DT36: 74 | DU36: 60 | DV36: 42 | DW36: 65 | DX36: 20 | DY36: 59 | DZ36: 73 | EA36: 100 | EB36: 100 | EC36: 37 | ED36: 37 | EE36: 52 | EF36: 2 | EG36: 32 | EH36: 42 | EI36: 46 | EJ36: 80 | EK36: 6 | EL36: 44 | EM36: 41 | EN36: 58 | EO36: 59 | EP36: 40 | EQ36: 60 | ER36: 8 | ES36: 75 | ET36: 62 | EU36: 65 | EV36: 80 | EW36: 57 | EX36: 74 | EY36: 65 | EZ36: 71 | FA36: 6 | FB36: 45 | FC36: 63 | FD36: 100 | FE36: 100 | FF36: 29 | FG36: 33 | FH36: 47 | FI36: 1 | FJ36: 37 | FK36: 48 | FL36: 46 | FM36: 97 | FN36: 5 | FO36: 40 | FP36: 32 | FQ36: 50 | FR36: 53 | FS36: 30 | FT36: 60 | FU36: 16 | FV36: 74 | FW36: 67 | FX36: 60 | FY36: 79 | FZ36: 53 | GA36: 67 | GB36: 70 | GC36: 69 | GD36: 7 | GE36: 40 | GF36: 57 | GG36: 100 | GH36: 100 | GJ36: 23 | GK36: 2 | GL36: 25 | GT36: -100 | GU36: -7
BV37: 22 | BW37: 46 | BX37: 50 | BY37: 68 | BZ37: 5 | CA37: 17 | CB37: 22 | CC37: 37 | CD37: 89 | CE37: 5 | CF37: 47 | CG37: 49 | CH37: 70 | CI37: 72 | CJ37: 52 | CK37: 103 | CL37: 22 | CM37: 85 | CN37: 43 | CO37: 75 | CP37: 102 | CQ37: 75 | CR37: 74 | CS37: 48 | CT37: 70 | CU37: 20 | CV37: 67 | CW37: 74 | CX37: 100 | CY37: 100 | CZ37: 45 | DA37: 49 | DB37: 62 | DC37: 3 | DD37: 18 | DE37: 24 | DF37: 25 | DG37: 87 | DH37: 3 | DI37: 46 | DJ37: 46 | DK37: 70 | DL37: 64 | DM37: 52 | DN37: 87 | DO37: 32 | DP37: 85 | DQ37: 41 | DR37: 72 | DS37: 112 | DT37: 74 | DU37: 61 | DV37: 45 | DW37: 69 | DX37: 25 | DY37: 61 | DZ37: 74 | EA37: 100 | EB37: 100 | EC37: 40 | ED37: 40 | EE37: 53 | EF37: 2 | EG37: 34 | EH37: 44 | EI37: 47 | EJ37: 82 | EK37: 6 | EL37: 45 | EM37: 42 | EN37: 61 | EO37: 62 | EP37: 41 | EQ37: 63 | ER37: 9 | ES37: 79 | ET37: 64 | EU37: 67 | EV37: 82 | EW37: 58 | EX37: 75 | EY37: 68 | EZ37: 73 | FA37: 7 | FB37: 47 | FC37: 64 | FD37: 100 | FE37: 100 | FF37: 32 | FG37: 36 | FH37: 48 | FI37: 1 | FJ37: 40 | FK37: 49 | FL37: 47 | FM37: 99 | FN37: 5 | FO37: 41 | FP37: 33 | FQ37: 53 | FR37: 55 | FS37: 31 | FT37: 61 | FU37: 20 | FV37: 75 | FW37: 68 | FX37: 63 | FY37: 81 | FZ37: 54 | GA37: 68 | GB37: 73 | GC37: 72 | GD37: 8 | GE37: 41 | GF37: 61 | GG37: 100 | GH37: 100 | GJ37: 24 | GK37: 2 | GL37: 25 | GT37: -99 | GU37: -7
BV38: 23 | BW38: 47 | BX38: 52 | BY38: 71 | BZ38: 7 | CA38: 20 | CB38: 25 | CC38: 40 | CD38: 91 | CE38: 6 | CF38: 49 | CG38: 50 | CH38: 72 | CI38: 73 | CJ38: 54 | CK38: 105 | CL38: 24 | CM38: 88 | CN38: 45 | CO38: 79 | CP38: 106 | CQ38: 80 | CR38: 75 | CS38: 50 | CT38: 73 | CU38: 21 | CV38: 68 | CW38: 75 | CX38: 100 | CY38: 100 | CZ38: 46 | DA38: 50 | DB38: 63 | DC38: 3 | DD38: 20 | DE38: 27 | DF38: 27 | DG38: 90 | DH38: 5 | DI38: 48 | DJ38: 47 | DK38: 73 | DL38: 68 | DM38: 54 | DN38: 92 | DO38: 37 | DP38: 90 | DQ38: 43 | DR38: 75 | DS38: 112 | DT38: 75 | DU38: 62 | DV38: 47 | DW38: 72 | DX38: 28 | DY38: 62 | DZ38: 75 | EA38: 100 | EB38: 100 | EC38: 42 | ED38: 41 | EE38: 55 | EF38: 2 | EG38: 37 | EH38: 45 | EI38: 48 | EJ38: 84 | EK38: 7 | EL38: 47 | EM38: 43 | EN38: 62 | EO38: 64 | EP38: 42 | EQ38: 66 | ER38: 12 | ES38: 80 | ET38: 67 | EU38: 70 | EV38: 85 | EW38: 60 | EX38: 76 | EY38: 71 | EZ38: 75 | FA38: 8 | FB38: 49 | FC38: 65 | FD38: 100 | FE38: 100 | FF38: 38 | FG38: 37 | FH38: 49 | FI38: 1 | FJ38: 41 | FK38: 50 | FL38: 48 | FM38: 100 | FN38: 8 | FO38: 42 | FP38: 34 | FQ38: 55 | FR38: 57 | FS38: 33 | FT38: 64 | FU38: 24 | FV38: 78 | FW38: 70 | FX38: 65 | FY38: 83 | FZ38: 56 | GA38: 70 | GB38: 74 | GC38: 75 | GD38: 9 | GE38: 42 | GF38: 62 | GG38: 100 | GH38: 100 | GJ38: 25 | GK38: 2 | GL38: 25 | GT38: -98 | GU38: -7
BV39: 24 | BW39: 49 | BX39: 56 | BY39: 73 | BZ39: 8 | CA39: 21 | CB39: 27 | CC39: 42 | CD39: 92 | CE39: 7 | CF39: 50 | CG39: 52 | CH39: 75 | CI39: 75 | CJ39: 57 | CK39: 107 | CL39: 28 | CM39: 92 | CN39: 50 | CO39: 82 | CP39: 108 | CQ39: 81 | CR39: 77 | CS39: 54 | CT39: 75 | CU39: 24 | CV39: 69 | CW39: 76 | CX39: 100 | CY39: 100 | CZ39: 47 | DA39: 52 | DB39: 63 | DC39: 3 | DD39: 22 | DE39: 31 | DF39: 32 | DG39: 90 | DH39: 5 | DI39: 49 | DJ39: 48 | DK39: 74 | DL39: 71 | DM39: 54 | DN39: 100 | DO39: 40 | DP39: 90 | DQ39: 46 | DR39: 79 | DS39: 112 | DT39: 77 | DU39: 65 | DV39: 50 | DW39: 75 | DX39: 30 | DY39: 65 | DZ39: 81 | EA39: 100 | EB39: 100 | EC39: 43 | ED39: 43 | EE39: 58 | EF39: 2 | EG39: 38 | EH39: 47 | EI39: 49 | EJ39: 85 | EK39: 9 | EL39: 48 | EM39: 44 | EN39: 65 | EO39: 67 | EP39: 42 | EQ39: 69 | ER39: 14 | ES39: 82 | ET39: 71 | EU39: 72 | EV39: 89 | EW39: 62 | EX39: 78 | EY39: 73 | EZ39: 78 | FA39: 9 | FB39: 50 | FC39: 66 | FD39: 100 | FE39: 100 | FF39: 40 | FG39: 40 | FH39: 50 | FI39: 1 | FJ39: 42 | FK39: 52 | FL39: 49 | FM39: 100 | FN39: 12 | FO39: 43 | FP39: 35 | FQ39: 57 | FR39: 59 | FS39: 34 | FT39: 65 | FU39: 26 | FV39: 82 | FW39: 73 | FX39: 68 | FY39: 85 | FZ39: 57 | GA39: 72 | GB39: 75 | GC39: 79 | GD39: 10 | GE39: 43 | GF39: 63 | GG39: 100 | GH39: 100 | GJ39: 26 | GK39: 2 | GL39: 25 | GT39: -97 | GU39: -7
BV40: 25 | BW40: 50 | BX40: 59 | BY40: 74 | BZ40: 8 | CA40: 22 | CB40: 29 | CC40: 44 | CD40: 93 | CE40: 9 | CF40: 53 | CG40: 55 | CH40: 78 | CI40: 77 | CJ40: 59 | CK40: 110 | CL40: 31 | CM40: 98 | CN40: 54 | CO40: 85 | CP40: 114 | CQ40: 85 | CR40: 79 | CS40: 57 | CT40: 79 | CU40: 28 | CV40: 71 | CW40: 78 | CX40: 100 | CY40: 100 | CZ40: 48 | DA40: 55 | DB40: 63 | DC40: 3 | DD40: 23 | DE40: 33 | DF40: 35 | DG40: 92 | DH40: 5 | DI40: 50 | DJ40: 49 | DK40: 75 | DL40: 73 | DM40: 57 | DN40: 105 | DO40: 44 | DP40: 92 | DQ40: 48 | DR40: 85 | DS40: 112 | DT40: 77 | DU40: 68 | DV40: 53 | DW40: 82 | DX40: 37 | DY40: 66 | DZ40: 83 | EA40: 100 | EB40: 100 | EC40: 45 | ED40: 44 | EE40: 60 | EF40: 3 | EG40: 40 | EH40: 50 | EI40: 50 | EJ40: 95 | EK40: 11 | EL40: 49 | EM40: 45 | EN40: 67 | EO40: 69 | EP40: 43 | EQ40: 72 | ER40: 15 | ES40: 85 | ET40: 73 | EU40: 74 | EV40: 95 | EW40: 64 | EX40: 79 | EY40: 75 | EZ40: 82 | FA40: 10 | FB40: 52 | FC40: 67 | FD40: 100 | FE40: 100 | FF40: 42 | FG40: 41 | FH40: 51 | FI40: 1 | FJ40: 43 | FK40: 54 | FL40: 50 | FM40: 102 | FN40: 13 | FO40: 45 | FP40: 36 | FQ40: 60 | FR40: 61 | FS40: 37 | FT40: 68 | FU40: 32 | FV40: 85 | FW40: 75 | FX40: 71 | FY40: 89 | FZ40: 59 | GA40: 73 | GB40: 77 | GC40: 81 | GD40: 17 | GE40: 44 | GF40: 65 | GG40: 100 | GH40: 100 | GJ40: 27 | GK40: 2 | GL40: 25 | GT40: -96 | GU40: -7
BV41: 26 | BW41: 51 | BX41: 61 | BY41: 75 | BZ41: 9 | CA41: 23 | CB41: 31 | CC41: 46 | CD41: 99 | CE41: 12 | CF41: 54 | CG41: 56 | CH41: 83 | CI41: 79 | CJ41: 60 | CK41: 110 | CL41: 34 | CM41: 101 | CN41: 57 | CO41: 88 | CP41: 114 | CQ41: 90 | CR41: 80 | CS41: 60 | CT41: 83 | CU41: 32 | CV41: 72 | CW41: 79 | CX41: 100 | CY41: 100 | CZ41: 50 | DA41: 58 | DB41: 63 | DC41: 3 | DD41: 23 | DE41: 36 | DF41: 40 | DG41: 95 | DH41: 8 | DI41: 52 | DJ41: 50 | DK41: 77 | DL41: 75 | DM41: 59 | DN41: 110 | DO41: 50 | DP41: 95 | DQ41: 50 | DR41: 88 | DS41: 112 | DT41: 77 | DU41: 69 | DV41: 55 | DW41: 85 | DX41: 40 | DY41: 67 | DZ41: 85 | EA41: 100 | EB41: 100 | EC41: 46 | ED41: 45 | EE41: 62 | EF41: 3 | EG41: 41 | EH41: 53 | EI41: 52 | EJ41: 97 | EK41: 12 | EL41: 50 | EM41: 46 | EN41: 69 | EO41: 71 | EP41: 44 | EQ41: 75 | ER41: 18 | ES41: 90 | ET41: 75 | EU41: 75 | EV41: 98 | EW41: 66 | EX41: 80 | EY41: 79 | EZ41: 85 | FA41: 12 | FB41: 54 | FC41: 68 | FD41: 100 | FE41: 100 | FF41: 43 | FG41: 42 | FH41: 52 | FI41: 2 | FJ41: 45 | FK41: 56 | FL41: 52 | FM41: 103 | FN41: 17 | FO41: 47 | FP41: 38 | FQ41: 63 | FR41: 63 | FS41: 38 | FT41: 72 | FU41: 36 | FV41: 91 | FW41: 80 | FX41: 73 | FY41: 95 | FZ41: 61 | GA41: 75 | GB41: 81 | GC41: 85 | GD41: 20 | GE41: 45 | GF41: 66 | GG41: 100 | GH41: 100 | GJ41: 28 | GK41: 2 | GL41: 25 | GT41: -95 | GU41: -7
A42: 1 | B42: =IF('DATOS Y RESPUESTAS'!C14="v",1,0) -> 0 | C42: =IF('DATOS Y RESPUESTAS'!C14="f",1,0) -> 1 | D42: 26 | E42: =IF('DATOS Y RESPUESTAS'!E14="v",1,0) -> 0 | F42: =IF('DATOS Y RESPUESTAS'!E14="f",1,0) -> 1 | H42: 51 | I42: =IF('DATOS Y RESPUESTAS'!G14="v",1,0) -> 0 | J42: =IF('DATOS Y RESPUESTAS'!G14="f",1,0) -> 1 | K42: 76 | L42: =IF('DATOS Y RESPUESTAS'!I14="v",1,0) -> 0 | M42: =IF('DATOS Y RESPUESTAS'!I14="f",1,0) -> 1 | N42: 101 | O42: =IF('DATOS Y RESPUESTAS'!K14="v",1,0) -> 0 | P42: =IF('DATOS Y RESPUESTAS'!K14="f",1,0) -> 1 | Q42: 126 | R42: =IF('DATOS Y RESPUESTAS'!M14="v",1,0) -> 0 | S42: =IF('DATOS Y RESPUESTAS'!M14="f",1,0) -> 1 | V42: 151 | X42: =IF('DATOS Y RESPUESTAS'!O14="v",1,0) -> 0 | Y42: =IF('DATOS Y RESPUESTAS'!O14="f",1,0) -> 1 | BV42: 27 | BW42: 54 | BX42: 62 | BY42: 76 | BZ42: 9 | CA42: 24 | CB42: 34 | CC42: 47 | CD42: 103 | CE42: 14 | CF42: 57 | CG42: 58 | CH42: 85 | CI42: 82 | CJ42: 61 | CK42: 111 | CL42: 40 | CM42: 105 | CN42: 61 | CO42: 94 | CP42: 114 | CQ42: 92 | CR42: 82 | CS42: 64 | CT42: 85 | CU42: 36 | CV42: 73 | CW42: 81 | CX42: 100 | CY42: 100 | CZ42: 51 | DA42: 59 | DB42: 65 | DC42: 4 | DD42: 24 | DE42: 37 | DF42: 42 | DG42: 98 | DH42: 8 | DI42: 54 | DJ42: 53 | DK42: 84 | DL42: 77 | DM42: 61 | DN42: 110 | DO42: 55 | DP42: 100 | DQ42: 54 | DR42: 98 | DS42: 112 | DT42: 80 | DU42: 70 | DV42: 59 | DW42: 89 | DX42: 43 | DY42: 70 | DZ42: 89 | EA42: 100 | EB42: 100 | EC42: 48 | ED42: 46 | EE42: 64 | EF42: 3 | EG42: 42 | EH42: 56 | EI42: 55 | EJ42: 102 | EK42: 15 | EL42: 51 | EM42: 47 | EN42: 71 | EO42: 73 | EP42: 45 | EQ42: 79 | ER42: 23 | ES42: 93 | ET42: 79 | EU42: 78 | EV42: 102 | EW42: 68 | EX42: 81 | EY42: 83 | EZ42: 91 | FA42: 13 | FB42: 55 | FC42: 69 | FD42: 100 | FE42: 100 | FF42: 45 | FG42: 44 | FH42: 54 | FI42: 3 | FJ42: 46 | FK42: 59 | FL42: 54 | FM42: 105 | FN42: 20 | FO42: 50 | FP42: 40 | FQ42: 64 | FR42: 65 | FS42: 40 | FT42: 75 | FU42: 40 | FV42: 93 | FW42: 83 | FX42: 75 | FY42: 100 | FZ42: 62 | GA42: 78 | GB42: 85 | GC42: 92 | GD42: 21 | GE42: 47 | GF42: 67 | GG42: 100 | GH42: 100 | GJ42: 29 | GK42: 2 | GL42: 25 | GT42: -94 | GU42: -7
A43: 2 | B43: =IF('DATOS Y RESPUESTAS'!C15="v",1,0) -> 1 | C43: =IF('DATOS Y RESPUESTAS'!C15="f",1,0) -> 0 | D43: 27 | E43: =IF('DATOS Y RESPUESTAS'!E15="v",1,0) -> 0 | F43: =IF('DATOS Y RESPUESTAS'!E15="f",1,0) -> 1 | H43: 52 | I43: =IF('DATOS Y RESPUESTAS'!G15="v",1,0) -> 0 | J43: =IF('DATOS Y RESPUESTAS'!G15="f",1,0) -> 1 | K43: 77 | L43: =IF('DATOS Y RESPUESTAS'!I15="v",1,0) -> 1 | M43: =IF('DATOS Y RESPUESTAS'!I15="f",1,0) -> 0 | N43: 102 | O43: =IF('DATOS Y RESPUESTAS'!K15="v",1,0) -> 0 | P43: =IF('DATOS Y RESPUESTAS'!K15="f",1,0) -> 1 | Q43: 127 | R43: =IF('DATOS Y RESPUESTAS'!M15="v",1,0) -> 0 | S43: =IF('DATOS Y RESPUESTAS'!M15="f",1,0) -> 1 | V43: 152 | X43: =IF('DATOS Y RESPUESTAS'!O15="v",1,0) -> 0 | Y43: =IF('DATOS Y RESPUESTAS'!O15="f",1,0) -> 1 | BV43: 28 | BW43: 56 | BX43: 63 | BY43: 77 | BZ43: 10 | CA43: 26 | CB43: 37 | CC43: 48 | CD43: 105 | CE43: 15 | CF43: 60 | CG43: 60 | CH43: 90 | CI43: 85 | CJ43: 62 | CK43: 111 | CL43: 44 | CM43: 109 | CN43: 65 | CO43: 97 | CP43: 114 | CQ43: 95 | CR43: 83 | CS43: 68 | CT43: 89 | CU43: 40 | CV43: 74 | CW43: 84 | CX43: 100 | CY43: 100 | CZ43: 53 | DA43: 60 | DB43: 67 | DC43: 6 | DD43: 27 | DE43: 40 | DF43: 45 | DG43: 105 | DH43: 10 | DI43: 56 | DJ43: 55 | DK43: 85 | DL43: 83 | DM43: 62 | DN43: 110 | DO43: 59 | DP43: 105 | DQ43: 60 | DR43: 101 | DS43: 112 | DT43: 85 | DU43: 71 | DV43: 62 | DW43: 96 | DX43: 45 | DY43: 72 | DZ43: 96 | EA43: 100 | EB43: 100 | EC43: 49 | ED43: 47 | EE43: 66 | EF43: 4 | EG43: 43 | EH43: 59 | EI43: 58 | EJ43: 104 | EK43: 16 | EL43: 54 | EM43: 48 | EN43: 73 | EO43: 75 | EP43: 46 | EQ43: 85 | ER43: 28 | ES43: 99 | ET43: 81 | EU43: 81 | EV43: 103 | EW43: 70 | EX43: 82 | EY43: 85 | EZ43: 95 | FA43: 16 | FB43: 57 | FC43: 70 | FD43: 100 | FE43: 100 | FF43: 46 | FG43: 46 | FH43: 57 | FI43: 3 | FJ43: 47 | FK43: 62 | FL43: 57 | FM43: 106 | FN43: 21 | FO43: 53 | FP43: 41 | FQ43: 69 | FR43: 68 | FS43: 41 | FT43: 85 | FU43: 42 | FV43: 99 | FW43: 85 | FX43: 80 | FY43: 102 | FZ43: 63 | GA43: 80 | GB43: 92 | GC43: 97 | GD43: 22 | GE43: 48 | GF43: 69 | GG43: 100 | GH43: 100 | GJ43: 30 | GK43: 2 | GL43: 25 | GT43: -93 | GU43: -7
A44: 3 | B44: =IF('DATOS Y RESPUESTAS'!C16="v",1,0) -> 0 | C44: =IF('DATOS Y RESPUESTAS'!C16="f",1,0) -> 1 | D44: 28 | E44: =IF('DATOS Y RESPUESTAS'!E16="v",1,0) -> 0 | F44: =IF('DATOS Y RESPUESTAS'!E16="f",1,0) -> 1 | H44: 53 | I44: =IF('DATOS Y RESPUESTAS'!G16="v",1,0) -> 0 | J44: =IF('DATOS Y RESPUESTAS'!G16="f",1,0) -> 1 | K44: 78 | L44: =IF('DATOS Y RESPUESTAS'!I16="v",1,0) -> 0 | M44: =IF('DATOS Y RESPUESTAS'!I16="f",1,0) -> 1 | N44: 103 | O44: =IF('DATOS Y RESPUESTAS'!K16="v",1,0) -> 0 | P44: =IF('DATOS Y RESPUESTAS'!K16="f",1,0) -> 1 | Q44: 128 | R44: =IF('DATOS Y RESPUESTAS'!M16="v",1,0) -> 0 | S44: =IF('DATOS Y RESPUESTAS'!M16="f",1,0) -> 1 | V44: 153 | X44: =IF('DATOS Y RESPUESTAS'!O16="v",1,0) -> 0 | Y44: =IF('DATOS Y RESPUESTAS'!O16="f",1,0) -> 1 | BV44: 29 | BW44: 59 | BX44: 65 | BY44: 78 | BZ44: 11 | CA44: 28 | CB44: 40 | CC44: 49 | CD44: 105 | CE44: 18 | CF44: 63 | CG44: 62 | CH44: 97 | CI44: 91 | CJ44: 65 | CK44: 114 | CL44: 48 | CM44: 111 | CN44: 69 | CO44: 102 | CP44: 114 | CQ44: 95 | CR44: 84 | CS44: 72 | CT44: 93 | CU44: 43 | CV44: 75 | CW44: 85 | CX44: 100 | CY44: 100 | CZ44: 57 | DA44: 63 | DB44: 71 | DC44: 8 | DD44: 29 | DE44: 41 | DF44: 46 | DG44: 110 | DH44: 13 | DI44: 57 | DJ44: 56 | DK44: 88 | DL44: 85 | DM44: 63 | DN44: 113 | DO44: 63 | DP44: 108 | DQ44: 64 | DR44: 105 | DS44: 112 | DT44: 98 | DU44: 72 | DV44: 64 | DW44: 106 | DX44: 48 | DY44: 73 | DZ44: 96 | EA44: 100 | EB44: 100 | EC44: 50 | ED44: 48 | EE44: 68 | EF44: 5 | EG44: 46 | EH44: 61 | EI44: 59 | EJ44: 106 | EK44: 17 | EL44: 56 | EM44: 49 | EN44: 75 | EO44: 80 | EP44: 47 | EQ44: 98 | ER44: 34 | ES44: 105 | ET44: 83 | EU44: 85 | EV44: 105 | EW44: 72 | EX44: 83 | EY44: 90 | EZ44: 101 | FA44: 19 | FB44: 58 | FC44: 71 | FD44: 100 | FE44: 100 | FF44: 48 | FG44: 47 | FH44: 59 | FI44: 4 | FJ44: 48 | FK44: 64 | FL44: 59 | FM44: 108 | FN44: 23 | FO44: 55 | FP44: 42 | FQ44: 72 | FR44: 71 | FS44: 42 | FT44: 97 | FU44: 44 | FV44: 105 | FW44: 92 | FX44: 83 | FY44: 105 | FZ44: 66 | GA44: 80 | GB44: 102 | GC44: 104 | GD44: 24 | GE44: 49 | GF44: 70 | GG44: 100 | GH44: 100 | GJ44: 31 | GK44: 2 | GL44: 25 | GT44: -92 | GU44: -7
A45: 4 | B45: =IF('DATOS Y RESPUESTAS'!C17="v",1,0) -> 1 | C45: =IF('DATOS Y RESPUESTAS'!C17="f",1,0) -> 0 | D45: 29 | E45: =IF('DATOS Y RESPUESTAS'!E17="v",1,0) -> 0 | F45: =IF('DATOS Y RESPUESTAS'!E17="f",1,0) -> 1 | H45: 54 | I45: =IF('DATOS Y RESPUESTAS'!G17="v",1,0) -> 1 | J45: =IF('DATOS Y RESPUESTAS'!G17="f",1,0) -> 0 | K45: 79 | L45: =IF('DATOS Y RESPUESTAS'!I17="v",1,0) -> 0 | M45: =IF('DATOS Y RESPUESTAS'!I17="f",1,0) -> 1 | N45: 104 | O45: =IF('DATOS Y RESPUESTAS'!K17="v",1,0) -> 0 | P45: =IF('DATOS Y RESPUESTAS'!K17="f",1,0) -> 1 | Q45: 129 | R45: =IF('DATOS Y RESPUESTAS'!M17="v",1,0) -> 1 | S45: =IF('DATOS Y RESPUESTAS'!M17="f",1,0) -> 0 | V45: 154 | X45: =IF('DATOS Y RESPUESTAS'!O17="v",1,0) -> 0 | Y45: =IF('DATOS Y RESPUESTAS'!O17="f",1,0) -> 1 | BV45: 30 | BW45: 62 | BX45: 69 | BY45: 79 | BZ45: 13 | CA45: 31 | CB45: 43 | CC45: 50 | CD45: 106 | CE45: 20 | CF45: 64 | CG45: 63 | CH45: 99 | CI45: 95 | CJ45: 67 | CK45: 115 | CL45: 50 | CM45: 112 | CN45: 71 | CO45: 105 | CP45: 115 | CQ45: 95 | CR45: 84 | CS45: 74 | CT45: 103 | CU45: 47 | CV45: 76 | CW45: 90 | CX45: 100 | CY45: 100 | CZ45: 60 | DA45: 63 | DB45: 75 | DC45: 8 | DD45: 30 | DE45: 43 | DF45: 47 | DG45: 110 | DH45: 20 | DI45: 59 | DJ45: 58 | DK45: 95 | DL45: 91 | DM45: 64 | DN45: 115 | DO45: 65 | DP45: 113 | DQ45: 65 | DR45: 105 | DS45: 112 | DT45: 102 | DU45: 75 | DV45: 66 | DW45: 106 | DX45: 50 | DY45: 73 | DZ45: 96 | EA45: 100 | EB45: 100 | EC45: 53 | ED45: 49 | EE45: 69 | EF45: 6 | EG45: 48 | EH45: 64 | EI45: 63 | EJ45: 107 | EK45: 20 | EL45: 57 | EM45: 49 | EN45: 79 | EO45: 85 | EP45: 48 | EQ45: 109 | ER45: 40 | ES45: 110 | ET45: 85 | EU45: 95 | EV45: 106 | EW45: 73 | EX45: 84 | EY45: 92 | EZ45: 109 | FA45: 22 | FB45: 59 | FC45: 73 | FD45: 100 | FE45: 100 | FF45: 49 | FG45: 48 | FH45: 61 | FI45: 5 | FJ45: 49 | FK45: 67 | FL45: 60 | FM45: 108 | FN45: 24 | FO45: 57 | FP45: 43 | FQ45: 75 | FR45: 75 | FS45: 43 | FT45: 108 | FU45: 47 | FV45: 108 | FW45: 94 | FX45: 85 | FY45: 106 | FZ45: 67 | GA45: 83 | GB45: 105 | GC45: 105 | GD45: 28 | GE45: 50 | GF45: 71 | GG45: 100 | GH45: 100 | GJ45: 32 | GK45: 2 | GL45: 25 | GT45: -91 | GU45: -7
A46: 5 | B46: =IF('DATOS Y RESPUESTAS'!C18="v",1,0) -> 0 | C46: =IF('DATOS Y RESPUESTAS'!C18="f",1,0) -> 1 | D46: 30 | E46: =IF('DATOS Y RESPUESTAS'!E18="v",1,0) -> 0 | F46: =IF('DATOS Y RESPUESTAS'!E18="f",1,0) -> 1 | H46: 55 | I46: =IF('DATOS Y RESPUESTAS'!G18="v",1,0) -> 0 | J46: =IF('DATOS Y RESPUESTAS'!G18="f",1,0) -> 1 | K46: 80 | L46: =IF('DATOS Y RESPUESTAS'!I18="v",1,0) -> 0 | M46: =IF('DATOS Y RESPUESTAS'!I18="f",1,0) -> 1 | N46: 105 | O46: =IF('DATOS Y RESPUESTAS'!K18="v",1,0) -> 0 | P46: =IF('DATOS Y RESPUESTAS'!K18="f",1,0) -> 1 | Q46: 130 | R46: =IF('DATOS Y RESPUESTAS'!M18="v",1,0) -> 0 | S46: =IF('DATOS Y RESPUESTAS'!M18="f",1,0) -> 1 | V46: 155 | X46: =IF('DATOS Y RESPUESTAS'!O18="v",1,0) -> 0 | Y46: =IF('DATOS Y RESPUESTAS'!O18="f",1,0) -> 1 | BV46: 31 | BW46: 64 | BX46: 70 | BY46: 80 | BZ46: 14 | CA46: 34 | CB46: 45 | CC46: 52 | CD46: 106 | CE46: 21 | CF46: 66 | CG46: 64 | CH46: 102 | CI46: 99 | CJ46: 68 | CK46: 115 | CL46: 54 | CM46: 112 | CN46: 73 | CO46: 108 | CP46: 115 | CQ46: 97 | CR46: 85 | CS46: 75 | CT46: 107 | CU46: 50 | CV46: 78 | CW46: 92 | CX46: 100 | CY46: 100 | CZ46: 64 | DA46: 66 | DB46: 77 | DC46: 11 | DD46: 33 | DE46: 45 | DF46: 48 | DG46: 110 | DH46: 23 | DI46: 63 | DJ46: 60 | DK46: 98 | DL46: 96 | DM46: 65 | DN46: 115 | DO46: 68 | DP46: 115 | DQ46: 69 | DR46: 105 | DS46: 112 | DT46: 106 | DU46: 80 | DV46: 71 | DW46: 106 | DX46: 53 | DY46: 74 | DZ46: 96 | EA46: 100 | EB46: 100 | EC46: 55 | ED46: 50 | EE46: 71 | EF46: 6 | EG46: 50 | EH46: 67 | EI46: 65 | EJ46: 109 | EK46: 21 | EL46: 58 | EM46: 50 | EN46: 82 | EO46: 94 | EP46: 49 | EQ46: 113 | ER46: 43 | ES46: 114 | ET46: 92 | EU46: 97 | EV46: 111 | EW46: 75 | EX46: 85 | EY46: 99 | EZ46: 110 | FA46: 25 | FB46: 60 | FC46: 74 | FD46: 100 | FE46: 100 | FF46: 50 | FG46: 49 | FH46: 62 | FI46: 5 | FJ46: 50 | FK46: 70 | FL46: 61 | FM46: 109 | FN46: 25 | FO46: 58 | FP46: 44 | FQ46: 80 | FR46: 79 | FS46: 44 | FT46: 114 | FU46: 50 | FV46: 112 | FW46: 96 | FX46: 92 | FY46: 109 | FZ46: 68 | GA46: 84 | GB46: 107 | GC46: 112 | GD46: 31 | GE46: 51 | GF46: 72 | GG46: 100 | GH46: 100 | GJ46: 33 | GK46: 2 | GL46: 25 | GT46: -90 | GU46: -7
A47: 6 | B47: =IF('DATOS Y RESPUESTAS'!C19="v",1,0) -> 1 | C47: =IF('DATOS Y RESPUESTAS'!C19="f",1,0) -> 0 | D47: 31 | E47: =IF('DATOS Y RESPUESTAS'!E19="v",1,0) -> 0 | F47: =IF('DATOS Y RESPUESTAS'!E19="f",1,0) -> 1 | H47: 56 | I47: =IF('DATOS Y RESPUESTAS'!G19="v",1,0) -> 0 | J47: =IF('DATOS Y RESPUESTAS'!G19="f",1,0) -> 1 | K47: 81 | L47: =IF('DATOS Y RESPUESTAS'!I19="v",1,0) -> 1 | M47: =IF('DATOS Y RESPUESTAS'!I19="f",1,0) -> 0 | N47: 106 | O47: =IF('DATOS Y RESPUESTAS'!K19="v",1,0) -> 0 | P47: =IF('DATOS Y RESPUESTAS'!K19="f",1,0) -> 1 | Q47: 131 | R47: =IF('DATOS Y RESPUESTAS'!M19="v",1,0) -> 0 | S47: =IF('DATOS Y RESPUESTAS'!M19="f",1,0) -> 1 | V47: 156 | X47: =IF('DATOS Y RESPUESTAS'!O19="v",1,0) -> 0 | Y47: =IF('DATOS Y RESPUESTAS'!O19="f",1,0) -> 1 | BV47: 32 | BW47: 67 | BX47: 72 | BY47: 81 | BZ47: 15 | CA47: 35 | CB47: 47 | CC47: 54 | CD47: 108 | CE47: 22 | CF47: 67 | CG47: 65 | CH47: 107 | CI47: 101 | CJ47: 69 | CK47: 115 | CL47: 57 | CM47: 112 | CN47: 75 | CO47: 110 | CP47: 115 | CQ47: 100 | CR47: 86 | CS47: 77 | CT47: 110 | CU47: 54 | CV47: 82 | CW47: 97 | CX47: 100 | CY47: 100 | CZ47: 64 | DA47: 67 | DB47: 78 | DC47: 13 | DD47: 35 | DE47: 48 | DF47: 50 | DG47: 113 | DH47: 26 | DI47: 65 | DJ47: 61 | DK47: 102 | DL47: 106 | DM47: 65 | DN47: 115 | DO47: 72 | DP47: 115 | DQ47: 74 | DR47: 105 | DS47: 115 | DT47: 111 | DU47: 81 | DV47: 73 | DW47: 113 | DX47: 58 | DY47: 75 | DZ47: 100 | EA47: 100 | EB47: 100 | EC47: 58 | ED47: 51 | EE47: 73 | EF47: 7 | EG47: 52 | EH47: 70 | EI47: 67 | EJ47: 109 | EK47: 23 | EL47: 60 | EM47: 51 | EN47: 85 | EO47: 97 | EP47: 50 | EQ47: 115 | ER47: 46 | ES47: 115 | ET47: 96 | EU47: 102 | EV47: 112 | EW47: 78 | EX47: 87 | EY47: 103 | EZ47: 114 | FA47: 32 | FB47: 61 | FC47: 75 | FD47: 100 | FE47: 100 | FF47: 55 | FG47: 50 | FH47: 64 | FI47: 6 | FJ47: 52 | FK47: 72 | FL47: 63 | FM47: 111 | FN47: 27 | FO47: 60 | FP47: 46 | FQ47: 85 | FR47: 85 | FS47: 45 | FT47: 115 | FU47: 54 | FV47: 115 | FW47: 100 | FX47: 98 | FY47: 114 | FZ47: 71 | GA47: 85 | GB47: 107 | GC47: 114 | GD47: 37 | GE47: 52 | GF47: 73 | GG47: 100 | GH47: 100 | GJ47: 34 | GK47: 2 | GL47: 25 | GT47: -89 | GU47: -7
A48: 7 | B48: =IF('DATOS Y RESPUESTAS'!C20="v",1,0) -> 0 | C48: =IF('DATOS Y RESPUESTAS'!C20="f",1,0) -> 1 | D48: 32 | E48: =IF('DATOS Y RESPUESTAS'!E20="v",1,0) -> 0 | F48: =IF('DATOS Y RESPUESTAS'!E20="f",1,0) -> 1 | H48: 57 | I48: =IF('DATOS Y RESPUESTAS'!G20="v",1,0) -> 0 | J48: =IF('DATOS Y RESPUESTAS'!G20="f",1,0) -> 1 | K48: 82 | L48: =IF('DATOS Y RESPUESTAS'!I20="v",1,0) -> 0 | M48: =IF('DATOS Y RESPUESTAS'!I20="f",1,0) -> 1 | N48: 107 | O48: =IF('DATOS Y RESPUESTAS'!K20="v",1,0) -> 0 | P48: =IF('DATOS Y RESPUESTAS'!K20="f",1,0) -> 1 | Q48: 132 | R48: =IF('DATOS Y RESPUESTAS'!M20="v",1,0) -> 0 | S48: =IF('DATOS Y RESPUESTAS'!M20="f",1,0) -> 1 | V48: 157 | X48: =IF('DATOS Y RESPUESTAS'!O20="v",1,0) -> 0 | Y48: =IF('DATOS Y RESPUESTAS'!O20="f",1,0) -> 1 | BV48: 33 | BW48: 69 | BX48: 74 | BY48: 83 | BZ48: 17 | CA48: 40 | CB48: 50 | CC48: 57 | CD48: 110 | CE48: 23 | CF48: 69 | CG48: 66 | CH48: 109 | CI48: 105 | CJ48: 70 | CK48: 115 | CL48: 60 | CM48: 113 | CN48: 77 | CO48: 112 | CP48: 115 | CQ48: 105 | CR48: 95 | CS48: 80 | CT48: 113 | CU48: 58 | CV48: 83 | CW48: 100 | CX48: 100 | CY48: 100 | CZ48: 65 | DA48: 68 | DB48: 80 | DC48: 16 | DD48: 37 | DE48: 50 | DF48: 52 | DG48: 113 | DH48: 29 | DI48: 67 | DJ48: 62 | DK48: 105 | DL48: 108 | DM48: 67 | DN48: 115 | DO48: 75 | DP48: 115 | DQ48: 75 | DR48: 113 | DS48: 115 | DT48: 111 | DU48: 81 | DV48: 75 | DW48: 115 | DX48: 60 | DY48: 77 | DZ48: 104 | EA48: 100 | EB48: 100 | EC48: 60 | ED48: 52 | EE48: 75 | EF48: 8 | EG48: 54 | EH48: 72 | EI48: 68 | EJ48: 110 | EK48: 25 | EL48: 62 | EM48: 52 | EN48: 91 | EO48: 100 | EP48: 51 | EQ48: 115 | ER48: 48 | ES48: 115 | ET48: 100 | EU48: 105 | EV48: 112 | EW48: 81 | EX48: 90 | EY48: 105 | EZ48: 114 | FA48: 40 | FB48: 62 | FC48: 79 | FD48: 100 | FE48: 100 | FF48: 57 | FG48: 52 | FH48: 67 | FI48: 6 | FJ48: 55 | FK48: 74 | FL48: 66 | FM48: 111 | FN48: 29 | FO48: 63 | FP48: 47 | FQ48: 91 | FR48: 89 | FS48: 46 | FT48: 115 | FU48: 58 | FV48: 115 | FW48: 104 | FX48: 105 | FY48: 115 | FZ48: 73 | GA48: 87 | GB48: 107 | GC48: 114 | GD48: 40 | GE48: 55 | GF48: 75 | GG48: 100 | GH48: 100 | GJ48: 35 | GK48: 2 | GL48: 25 | GT48: -88 | GU48: -7
A49: 8 | B49: =IF('DATOS Y RESPUESTAS'!C21="v",1,0) -> 0 | C49: =IF('DATOS Y RESPUESTAS'!C21="f",1,0) -> 1 | D49: 33 | E49: =IF('DATOS Y RESPUESTAS'!E21="v",1,0) -> 0 | F49: =IF('DATOS Y RESPUESTAS'!E21="f",1,0) -> 1 | H49: 58 | I49: =IF('DATOS Y RESPUESTAS'!G21="v",1,0) -> 0 | J49: =IF('DATOS Y RESPUESTAS'!G21="f",1,0) -> 1 | K49: 83 | L49: =IF('DATOS Y RESPUESTAS'!I21="v",1,0) -> 0 | M49: =IF('DATOS Y RESPUESTAS'!I21="f",1,0) -> 1 | N49: 108 | O49: =IF('DATOS Y RESPUESTAS'!K21="v",1,0) -> 1 | P49: =IF('DATOS Y RESPUESTAS'!K21="f",1,0) -> 0 | Q49: 133 | R49: =IF('DATOS Y RESPUESTAS'!M21="v",1,0) -> 0 | S49: =IF('DATOS Y RESPUESTAS'!M21="f",1,0) -> 1 | V49: 158 | X49: =IF('DATOS Y RESPUESTAS'!O21="v",1,0) -> 0 | Y49: =IF('DATOS Y RESPUESTAS'!O21="f",1,0) -> 1 | BV49: 34 | BW49: 72 | BX49: 75 | BY49: 84 | BZ49: 20 | CA49: 41 | CB49: 55 | CC49: 60 | CD49: 113 | CE49: 25 | CF49: 72 | CG49: 67 | CH49: 114 | CI49: 108 | CJ49: 71 | CK49: 115 | CL49: 62 | CM49: 115 | CN49: 81 | CO49: 114 | CP49: 115 | CQ49: 107 | CR49: 95 | CS49: 81 | CT49: 115 | CU49: 61 | CV49: 85 | CW49: 107 | CX49: 100 | CY49: 100 | CZ49: 68 | DA49: 70 | DB49: 85 | DC49: 20 | DD49: 40 | DE49: 55 | DF49: 59 | DG49: 113 | DH49: 31 | DI49: 68 | DJ49: 64 | DK49: 109 | DL49: 108 | DM49: 69 | DN49: 115 | DO49: 83 | DP49: 115 | DQ49: 79 | DR49: 113 | DS49: 115 | DT49: 111 | DU49: 82 | DV49: 77 | DW49: 115 | DX49: 63 | DY49: 77 | DZ49: 108 | EA49: 100 | EB49: 100 | EC49: 61 | ED49: 54 | EE49: 78 | EF49: 9 | EG49: 57 | EH49: 73 | EI49: 70 | EJ49: 111 | EK49: 27 | EL49: 65 | EM49: 54 | EN49: 98 | EO49: 103 | EP49: 52 | EQ49: 115 | ER49: 50 | ES49: 115 | ET49: 101 | EU49: 110 | EV49: 114 | EW49: 85 | EX49: 93 | EY49: 106 | EZ49: 114 | FA49: 42 | FB49: 64 | FC49: 85 | FD49: 100 | FE49: 100 | FF49: 58 | FG49: 53 | FH49: 70 | FI49: 7 | FJ49: 57 | FK49: 75 | FL49: 68 | FM49: 111 | FN49: 30 | FO49: 64 | FP49: 48 | FQ49: 95 | FR49: 98 | FS49: 47 | FT49: 115 | FU49: 62 | FV49: 115 | FW49: 107 | FX49: 108 | FY49: 115 | FZ49: 75 | GA49: 90 | GB49: 108 | GC49: 115 | GD49: 42 | GE49: 57 | GF49: 81 | GG49: 100 | GH49: 100 | GJ49: 36 | GK49: 2 | GL49: 25 | GT49: -87 | GU49: -7
A50: 9 | B50: =IF('DATOS Y RESPUESTAS'!C22="v",1,0) -> 1 | C50: =IF('DATOS Y RESPUESTAS'!C22="f",1,0) -> 0 | D50: 34 | E50: =IF('DATOS Y RESPUESTAS'!E22="v",1,0) -> 0 | F50: =IF('DATOS Y RESPUESTAS'!E22="f",1,0) -> 1 | H50: 59 | I50: =IF('DATOS Y RESPUESTAS'!G22="v",1,0) -> 0 | J50: =IF('DATOS Y RESPUESTAS'!G22="f",1,0) -> 1 | K50: 84 | L50: =IF('DATOS Y RESPUESTAS'!I22="v",1,0) -> 0 | M50: =IF('DATOS Y RESPUESTAS'!I22="f",1,0) -> 1 | N50: 109 | O50: =IF('DATOS Y RESPUESTAS'!K22="v",1,0) -> 1 | P50: =IF('DATOS Y RESPUESTAS'!K22="f",1,0) -> 0 | Q50: 134 | R50: =IF('DATOS Y RESPUESTAS'!M22="v",1,0) -> 0 | S50: =IF('DATOS Y RESPUESTAS'!M22="f",1,0) -> 1 | V50: 159 | X50: =IF('DATOS Y RESPUESTAS'!O22="v",1,0) -> 1 | Y50: =IF('DATOS Y RESPUESTAS'!O22="f",1,0) -> 0 | BV50: 35 | BW50: 74 | BX50: 77 | BY50: 85 | BZ50: 21 | CA50: 44 | CB50: 59 | CC50: 63 | CD50: 114 | CE50: 29 | CF50: 74 | CG50: 69 | CH50: 115 | CI50: 109 | CJ50: 73 | CK50: 115 | CL50: 66 | CM50: 115 | CN50: 83 | CO50: 114 | CP50: 115 | CQ50: 110 | CR50: 95 | CS50: 83 | CT50: 115 | CU50: 65 | CV50: 89 | CW50: 110 | CX50: 100 | CY50: 100 | CZ50: 70 | DA50: 73 | DB50: 88 | DC50: 21 | DD50: 42 | DE50: 57 | DF50: 60 | DG50: 113 | DH50: 33 | DI50: 69 | DJ50: 65 | DK50: 112 | DL50: 110 | DM50: 70 | DN50: 115 | DO50: 85 | DP50: 115 | DQ50: 81 | DR50: 115 | DS50: 115 | DT50: 111 | DU50: 85 | DV50: 80 | DW50: 115 | DX50: 66 | DY50: 81 | DZ50: 112 | EA50: 100 | EB50: 100 | EC50: 64 | ED50: 55 | EE50: 79 | EF50: 12 | EG50: 61 | EH50: 75 | EI50: 71 | EJ50: 111 | EK50: 29 | EL50: 67 | EM50: 55 | EN50: 107 | EO50: 108 | EP50: 54 | EQ50: 115 | ER50: 54 | ES50: 115 | ET50: 102 | EU50: 112 | EV50: 115 | EW50: 94 | EX50: 97 | EY50: 107 | EZ50: 115 | FA50: 47 | FB50: 66 | FC50: 94 | FD50: 100 | FE50: 100 | FF50: 60 | FG50: 55 | FH50: 71 | FI50: 10 | FJ50: 60 | FK50: 78 | FL50: 71 | FM50: 111 | FN50: 32 | FO50: 67 | FP50: 49 | FQ50: 101 | FR50: 101 | FS50: 48 | FT50: 115 | FU50: 66 | FV50: 115 | FW50: 109 | FX50: 110 | FY50: 115 | FZ50: 84 | GA50: 92 | GB50: 108 | GC50: 115 | GD50: 43 | GE50: 59 | GF50: 85 | GG50: 100 | GH50: 100 | GJ50: 37 | GK50: 2 | GL50: 25 | GT50: -86 | GU50: -7
